Workbook
Name NativeTimeline_Date: #N/A

Sheet P
A1: Reservoir A - Collection to Storage and Withdrawal from Storage (30-day rule)
M3: =SUM(M2476:M2840) -> 80850 | N3: =SUM(N2476:N2840) -> 33000 | S3: =SUM(S2476:S2840) -> -71900 | T3: =SUM(T2476:T2840) -> -33000
D4: INPUT | G4: INPUT/Calc
M5: For Water Rts Reports | S5: For Water Rts Reports
A6: 1 | D6: 2 | E6: 3 | F6: 4 | G6: 4.1 | H6: 4.2 | I6: 5 | L6: 6 | M6: 7 | N6: 8 | S6: 10 | T6: 11
A7: DATA | I7: Collection to Storage | Q7: Withdrawal from Storage
A8: Date | B8: Year | C8: month | D8: Reservoir A | E8: Storage Change | F8: Storage Gain | G8: Moving Maximum from Starting Date | H8: check (starting date) | I8: Initial Collection to Storage | J8: Forward 30-day Moving Minimum | K8: +ΔS | L8: Refill Collection | M8: Total Collection to Storage | N8: Regulatory Collection to Storage | O8: Cumulative Initial Collection between Reg Collections | P8: Remaining Cumulative Reg Collection | Q8: Storage Loss | R8: WD | S8: WD from Storage | T8: Regulatory WD | V8: Manual Corrections
D9: (AF) | E9: (AF) | F9: (AF) | I9: (AF) | L9: (AF) | M9: (AF) | N9: (AF) | Q9: (AF) | S9: (AF) | T9: (AF)
A10: 43100 | B10: =YEAR(A10) -> 2017 | C10: =MONTH(A10) -> 12 | D10: 192770 | G10: =MAX($D$10:D10) -> 192770
A11: 43101 | B11: =YEAR(A11) -> 2018 | C11: =MONTH(A11) -> 1 | D11: 193200 | E11: =+D11-D10 -> 430 | F11: =IF(E11>0,E11,0) -> 430 | G11: =MAX($D$10:D11) -> 193200 | I11: =MAX(0,+G11-G10) -> 430 | J11: =MIN(D11:D40) -> 180590 | K11: =MAX(0,+J11-J10) -> 180590 | L11: =MIN(K11,F11-I11) -> 0 | M11: =+I11+L11 -> 430 | N11: =+F11-M11 -> 0 | O11: =MAX(0,IF(AND(I11=0,N11>0),0,O10+I11+S10)) -> 430 | P11: =MAX(0,P10+N11+T10) -> 0 | Q11: =IF(E11<0,E11,0) -> 0 | R11: =MIN(0,+Q11+P10+T10) -> 0 | S11: =MAX(Q11,IF(O11>0,MAX(-O11,Q11),R11)) -> 0 | T11: =+Q11-S11 -> 0
A12: 43102 | B12: =YEAR(A12) -> 2018 | C12: =MONTH(A12) -> 1 | D12: 193720 | E12: =+D12-D11 -> 520 | F12: =IF(E12>0,E12,0) -> 520 | G12: =MAX($D$10:D12) -> 193720 | I12: =MAX(0,+G12-G11) -> 520 | J12: =MIN(D12:D41) -> 180590 | K12: =MAX(0,+J12-J11) -> 0 | L12: =MIN(K12,F12-I12) -> 0 | M12: =+I12+L12 -> 520 | N12: =+F12-M12 -> 0 | O12: =MAX(0,IF(AND(I12=0,N12>0),0,O11+I12+S11)) -> 950 | P12: =MAX(0,P11+N12+T11) -> 0 | Q12: =IF(E12<0,E12,0) -> 0 | R12: =MIN(0,+Q12+P11+T11) -> 0 | S12: =MAX(Q12,IF(O12>0,MAX(-O12,Q12),R12)) -> 0 | T12: =+Q12-S12 -> 0
A13: 43103 | B13: =YEAR(A13) -> 2018 | C13: =MONTH(A13) -> 1 | D13: 194090 | E13: =+D13-D12 -> 370 | F13: =IF(E13>0,E13,0) -> 370 | G13: =MAX($D$10:D13) -> 194090 | I13: =MAX(0,+G13-G12) -> 370 | J13: =MIN(D13:D42) -> 180590 | K13: =MAX(0,+J13-J12) -> 0 | L13: =MIN(K13,F13-I13) -> 0 | M13: =+I13+L13 -> 370 | N13: =+F13-M13 -> 0 | O13: =MAX(0,IF(AND(I13=0,N13>0),0,O12+I13+S12)) -> 1320 | P13: =MAX(0,P12+N13+T12) -> 0 | Q13: =IF(E13<0,E13,0) -> 0 | R13: =MIN(0,+Q13+P12+T12) -> 0 | S13: =MAX(Q13,IF(O13>0,MAX(-O13,Q13),R13)) -> 0 | T13: =+Q13-S13 -> 0
A14: 43104 | B14: =YEAR(A14) -> 2018 | C14: =MONTH(A14) -> 1 | D14: 194780 | E14: =+D14-D13 -> 690 | F14: =IF(E14>0,E14,0) -> 690 | G14: =MAX($D$10:D14) -> 194780 | I14: =MAX(0,+G14-G13) -> 690 | J14: =MIN(D14:D43) -> 180590 | K14: =MAX(0,+J14-J13) -> 0 | L14: =MIN(K14,F14-I14) -> 0 | M14: =+I14+L14 -> 690 | N14: =+F14-M14 -> 0 | O14: =MAX(0,IF(AND(I14=0,N14>0),0,O13+I14+S13)) -> 2010 | P14: =MAX(0,P13+N14+T13) -> 0 | Q14: =IF(E14<0,E14,0) -> 0 | R14: =MIN(0,+Q14+P13+T13) -> 0 | S14: =MAX(Q14,IF(O14>0,MAX(-O14,Q14),R14)) -> 0 | T14: =+Q14-S14 -> 0
A15: 43105 | B15: =YEAR(A15) -> 2018 | C15: =MONTH(A15) -> 1 | D15: 195360 | E15: =+D15-D14 -> 580 | F15: =IF(E15>0,E15,0) -> 580 | G15: =MAX($D$10:D15) -> 195360 | I15: =MAX(0,+G15-G14) -> 580 | J15: =MIN(D15:D44) -> 180590 | K15: =MAX(0,+J15-J14) -> 0 | L15: =MIN(K15,F15-I15) -> 0 | M15: =+I15+L15 -> 580 | N15: =+F15-M15 -> 0 | O15: =MAX(0,IF(AND(I15=0,N15>0),0,O14+I15+S14)) -> 2590 | P15: =MAX(0,P14+N15+T14) -> 0 | Q15: =IF(E15<0,E15,0) -> 0 | R15: =MIN(0,+Q15+P14+T14) -> 0 | S15: =MAX(Q15,IF(O15>0,MAX(-O15,Q15),R15)) -> 0 | T15: =+Q15-S15 -> 0
A16: 43106 | B16: =YEAR(A16) -> 2018 | C16: =MONTH(A16) -> 1 | D16: 196210 | E16: =+D16-D15 -> 850 | F16: =IF(E16>0,E16,0) -> 850 | G16: =MAX($D$10:D16) -> 196210 | I16: =MAX(0,+G16-G15) -> 850 | J16: =MIN(D16:D45) -> 180590 | K16: =MAX(0,+J16-J15) -> 0 | L16: =MIN(K16,F16-I16) -> 0 | M16: =+I16+L16 -> 850 | N16: =+F16-M16 -> 0 | O16: =MAX(0,IF(AND(I16=0,N16>0),0,O15+I16+S15)) -> 3440 | P16: =MAX(0,P15+N16+T15) -> 0 | Q16: =IF(E16<0,E16,0) -> 0 | R16: =MIN(0,+Q16+P15+T15) -> 0 | S16: =MAX(Q16,IF(O16>0,MAX(-O16,Q16),R16)) -> 0 | T16: =+Q16-S16 -> 0
A17: 43107 | B17: =YEAR(A17) -> 2018 | C17: =MONTH(A17) -> 1 | D17: 197470 | E17: =+D17-D16 -> 1260 | F17: =IF(E17>0,E17,0) -> 1260 | G17: =MAX($D$10:D17) -> 197470 | I17: =MAX(0,+G17-G16) -> 1260 | J17: =MIN(D17:D46) -> 180590 | K17: =MAX(0,+J17-J16) -> 0 | L17: =MIN(K17,F17-I17) -> 0 | M17: =+I17+L17 -> 1260 | N17: =+F17-M17 -> 0 | O17: =MAX(0,IF(AND(I17=0,N17>0),0,O16+I17+S16)) -> 4700 | P17: =MAX(0,P16+N17+T16) -> 0 | Q17: =IF(E17<0,E17,0) -> 0 | R17: =MIN(0,+Q17+P16+T16) -> 0 | S17: =MAX(Q17,IF(O17>0,MAX(-O17,Q17),R17)) -> 0 | T17: =+Q17-S17 -> 0
A18: 43108 | B18: =YEAR(A18) -> 2018 | C18: =MONTH(A18) -> 1 | D18: 197280 | E18: =+D18-D17 -> -190 | F18: =IF(E18>0,E18,0) -> 0 | G18: =MAX($D$10:D18) -> 197470 | I18: =MAX(0,+G18-G17) -> 0 | J18: =MIN(D18:D47) -> 180590 | K18: =MAX(0,+J18-J17) -> 0 | L18: =MIN(K18,F18-I18) -> 0 | M18: =+I18+L18 -> 0 | N18: =+F18-M18 -> 0 | O18: =MAX(0,IF(AND(I18=0,N18>0),0,O17+I18+S17)) -> 4700 | P18: =MAX(0,P17+N18+T17) -> 0 | Q18: =IF(E18<0,E18,0) -> -190 | R18: =MIN(0,+Q18+P17+T17) -> -190 | S18: =MAX(Q18,IF(O18>0,MAX(-O18,Q18),R18)) -> -190 | T18: =+Q18-S18 -> 0
A19: 43109 | B19: =YEAR(A19) -> 2018 | C19: =MONTH(A19) -> 1 | D19: 197580 | E19: =+D19-D18 -> 300 | F19: =IF(E19>0,E19,0) -> 300 | G19: =MAX($D$10:D19) -> 197580 | I19: =MAX(0,+G19-G18) -> 110 | J19: =MIN(D19:D48) -> 180590 | K19: =MAX(0,+J19-J18) -> 0 | L19: =MIN(K19,F19-I19) -> 0 | M19: =+I19+L19 -> 110 | N19: =+F19-M19 -> 190 | O19: =MAX(0,IF(AND(I19=0,N19>0),0,O18+I19+S18)) -> 4620 | P19: =MAX(0,P18+N19+T18) -> 190 | Q19: =IF(E19<0,E19,0) -> 0 | R19: =MIN(0,+Q19+P18+T18) -> 0 | S19: =MAX(Q19,IF(O19>0,MAX(-O19,Q19),R19)) -> 0 | T19: =+Q19-S19 -> 0
A20: 43110 | B20: =YEAR(A20) -> 2018 | C20: =MONTH(A20) -> 1 | D20: 196450 | E20: =+D20-D19 -> -1130 | F20: =IF(E20>0,E20,0) -> 0 | G20: =MAX($D$10:D20) -> 197580 | I20: =MAX(0,+G20-G19) -> 0 | J20: =MIN(D20:D49) -> 180590 | K20: =MAX(0,+J20-J19) -> 0 | L20: =MIN(K20,F20-I20) -> 0 | M20: =+I20+L20 -> 0 | N20: =+F20-M20 -> 0 | O20: =MAX(0,IF(AND(I20=0,N20>0),0,O19+I20+S19)) -> 4620 | P20: =MAX(0,P19+N20+T19) -> 190 | Q20: =IF(E20<0,E20,0) -> -1130 | R20: =MIN(0,+Q20+P19+T19) -> -940 | S20: =MAX(Q20,IF(O20>0,MAX(-O20,Q20),R20)) -> -1130 | T20: =+Q20-S20 -> 0
A21: 43111 | B21: =YEAR(A21) -> 2018 | C21: =MONTH(A21) -> 1 | D21: 195320 | E21: =+D21-D20 -> -1130 | F21: =IF(E21>0,E21,0) -> 0 | G21: =MAX($D$10:D21) -> 197580 | I21: =MAX(0,+G21-G20) -> 0 | J21: =MIN(D21:D50) -> 180590 | K21: =MAX(0,+J21-J20) -> 0 | L21: =MIN(K21,F21-I21) -> 0 | M21: =+I21+L21 -> 0 | N21: =+F21-M21 -> 0 | O21: =MAX(0,IF(AND(I21=0,N21>0),0,O20+I21+S20)) -> 3490 | P21: =MAX(0,P20+N21+T20) -> 190 | Q21: =IF(E21<0,E21,0) -> -1130 | R21: =MIN(0,+Q21+P20+T20) -> -940 | S21: =MAX(Q21,IF(O21>0,MAX(-O21,Q21),R21)) -> -1130 | T21: =+Q21-S21 -> 0
A22: 43112 | B22: =YEAR(A22) -> 2018 | C22: =MONTH(A22) -> 1 | D22: 194130 | E22: =+D22-D21 -> -1190 | F22: =IF(E22>0,E22,0) -> 0 | G22: =MAX($D$10:D22) -> 197580 | I22: =MAX(0,+G22-G21) -> 0 | J22: =MIN(D22:D51) -> 180590 | K22: =MAX(0,+J22-J21) -> 0 | L22: =MIN(K22,F22-I22) -> 0 | M22: =+I22+L22 -> 0 | N22: =+F22-M22 -> 0 | O22: =MAX(0,IF(AND(I22=0,N22>0),0,O21+I22+S21)) -> 2360 | P22: =MAX(0,P21+N22+T21) -> 190 | Q22: =IF(E22<0,E22,0) -> -1190 | R22: =MIN(0,+Q22+P21+T21) -> -1000 | S22: =MAX(Q22,IF(O22>0,MAX(-O22,Q22),R22)) -> -1190 | T22: =+Q22-S22 -> 0
... A33: 43123 | B33: =YEAR(A33) -> 2018 | C33: =MONTH(A33) -> 1 | D33: 180630 | E33: =+D33-D32 -> -210 | F33: =IF(E33>0,E33,0) -> 0 | G33: =MAX($D$10:D33) -> 197580 | I33: =MAX(0,+G33-G32) -> 0 | J33: =MIN(D33:D62) -> 180590 | K33: =MAX(0,+J33-J32) -> 0 | L33: =MIN(K33,F33-I33) -> 0 | M33: =+I33+L33 -> 0 | N33: =+F33-M33 -> 0 | O33: =MAX(0,IF(AND(I33=0,N33>0),0,O32+I33+S32)) -> 0 | P33: =MAX(0,P32+N33+T32) -> 0 | Q33: =IF(E33<0,E33,0) -> -210 | R33: =MIN(0,+Q33+P32+T32) -> -210 | S33: =MAX(Q33,IF(O33>0,MAX(-O33,Q33),R33)) -> -210 | T33: =+Q33-S33 -> 0
A34: 43124 | B34: =YEAR(A34) -> 2018 | C34: =MONTH(A34) -> 1 | D34: 180590 | E34: =+D34-D33 -> -40 | F34: =IF(E34>0,E34,0) -> 0 | G34: =MAX($D$34:D34) -> 180590 | H34: <----- | I34: =MAX(0,+G34-G33) -> 0 | J34: =MIN(D34:D63) -> 180590 | K34: =MAX(0,+J34-J33) -> 0 | L34: =MIN(K34,F34-I34) -> 0 | M34: =+I34+L34 -> 0 | N34: =+F34-M34 -> 0 | O34: =MAX(0,IF(AND(I34=0,N34>0),0,O33+I34+S33)) -> 0 | P34: =MAX(0,P33+N34+T33) -> 0 | Q34: =IF(E34<0,E34,0) -> -40 | R34: =MIN(0,+Q34+P33+T33) -> -40 | S34: =MAX(Q34,IF(O34>0,MAX(-O34,Q34),R34)) -> -40 | T34: =+Q34-S34 -> 0
A35: 43125 | B35: =YEAR(A35) -> 2018 | C35: =MONTH(A35) -> 1 | D35: 180630 | E35: =+D35-D34 -> 40 | F35: =IF(E35>0,E35,0) -> 40 | G35: =MAX($D$34:D35) -> 180630 | I35: =MAX(0,+G35-G34) -> 40 | J35: =MIN(D35:D64) -> 180630 | K35: =MAX(0,+J35-J34) -> 40 | L35: =MIN(K35,F35-I35) -> 0 | M35: =+I35+L35 -> 40 | N35: =+F35-M35 -> 0 | O35: =MAX(0,IF(AND(I35=0,N35>0),0,O34+I35+S34)) -> 0 | P35: =MAX(0,P34+N35+T34) -> 0 | Q35: =IF(E35<0,E35,0) -> 0 | R35: =MIN(0,+Q35+P34+T34) -> 0 | S35: =MAX(Q35,IF(O35>0,MAX(-O35,Q35),R35)) -> 0 | T35: =+Q35-S35 -> 0
A36: 43126 | B36: =YEAR(A36) -> 2018 | C36: =MONTH(A36) -> 1 | D36: 180730 | E36: =+D36-D35 -> 100 | F36: =IF(E36>0,E36,0) -> 100 | G36: =MAX($D$34:D36) -> 180730 | I36: =MAX(0,+G36-G35) -> 100 | J36: =MIN(D36:D65) -> 180630 | K36: =MAX(0,+J36-J35) -> 0 | L36: =MIN(K36,F36-I36) -> 0 | M36: =+I36+L36 -> 100 | N36: =+F36-M36 -> 0 | O36: =MAX(0,IF(AND(I36=0,N36>0),0,O35+I36+S35)) -> 100 | P36: =MAX(0,P35+N36+T35) -> 0 | Q36: =IF(E36<0,E36,0) -> 0 | R36: =MIN(0,+Q36+P35+T35) -> 0 | S36: =MAX(Q36,IF(O36>0,MAX(-O36,Q36),R36)) -> 0 | T36: =+Q36-S36 -> 0
A37: 43127 | B37: =YEAR(A37) -> 2018 | C37: =MONTH(A37) -> 1 | D37: 180630 | E37: =+D37-D36 -> -100 | F37: =IF(E37>0,E37,0) -> 0 | G37: =MAX($D$34:D37) -> 180730 | I37: =MAX(0,+G37-G36) -> 0 | J37: =MIN(D37:D66) -> 180630 | K37: =MAX(0,+J37-J36) -> 0 | L37: =MIN(K37,F37-I37) -> 0 | M37: =+I37+L37 -> 0 | N37: =+F37-M37 -> 0 | O37: =MAX(0,IF(AND(I37=0,N37>0),0,O36+I37+S36)) -> 100 | P37: =MAX(0,P36+N37+T36) -> 0 | Q37: =IF(E37<0,E37,0) -> -100 | R37: =MIN(0,+Q37+P36+T36) -> -100 | S37: =MAX(Q37,IF(O37>0,MAX(-O37,Q37),R37)) -> -100 | T37: =+Q37-S37 -> 0
A38: 43128 | B38: =YEAR(A38) -> 2018 | C38: =MONTH(A38) -> 1 | D38: 181020 | E38: =+D38-D37 -> 390 | F38: =IF(E38>0,E38,0) -> 390 | G38: =MAX($D$34:D38) -> 181020 | I38: =MAX(0,+G38-G37) -> 290 | J38: =MIN(D38:D67) -> 180920 | K38: =MAX(0,+J38-J37) -> 290 | L38: =MIN(K38,F38-I38) -> 100 | M38: =+I38+L38 -> 390 | N38: =+F38-M38 -> 0 | O38: =MAX(0,IF(AND(I38=0,N38>0),0,O37+I38+S37)) -> 290 | P38: =MAX(0,P37+N38+T37) -> 0 | Q38: =IF(E38<0,E38,0) -> 0 | R38: =MIN(0,+Q38+P37+T37) -> 0 | S38: =MAX(Q38,IF(O38>0,MAX(-O38,Q38),R38)) -> 0 | T38: =+Q38-S38 -> 0
A39: 43129 | B39: =YEAR(A39) -> 2018 | C39: =MONTH(A39) -> 1 | D39: 181420 | E39: =+D39-D38 -> 400 | F39: =IF(E39>0,E39,0) -> 400 | G39: =MAX($D$34:D39) -> 181420 | I39: =MAX(0,+G39-G38) -> 400 | J39: =MIN(D39:D68) -> 180920 | K39: =MAX(0,+J39-J38) -> 0 | L39: =MIN(K39,F39-I39) -> 0 | M39: =+I39+L39 -> 400 | N39: =+F39-M39 -> 0 | O39: =MAX(0,IF(AND(I39=0,N39>0),0,O38+I39+S38)) -> 690 | P39: =MAX(0,P38+N39+T38) -> 0 | Q39: =IF(E39<0,E39,0) -> 0 | R39: =MIN(0,+Q39+P38+T38) -> 0 | S39: =MAX(Q39,IF(O39>0,MAX(-O39,Q39),R39)) -> 0 | T39: =+Q39-S39 -> 0
A40: 43130 | B40: =YEAR(A40) -> 2018 | C40: =MONTH(A40) -> 1 | D40: 181660 | E40: =+D40-D39 -> 240 | F40: =IF(E40>0,E40,0) -> 240 | G40: =MAX($D$34:D40) -> 181660 | I40: =MAX(0,+G40-G39) -> 240 | J40: =MIN(D40:D69) -> 180920 | K40: =MAX(0,+J40-J39) -> 0 | L40: =MIN(K40,F40-I40) -> 0 | M40: =+I40+L40 -> 240 | N40: =+F40-M40 -> 0 | O40: =MAX(0,IF(AND(I40=0,N40>0),0,O39+I40+S39)) -> 930 | P40: =MAX(0,P39+N40+T39) -> 0 | Q40: =IF(E40<0,E40,0) -> 0 | R40: =MIN(0,+Q40+P39+T39) -> 0 | S40: =MAX(Q40,IF(O40>0,MAX(-O40,Q40),R40)) -> 0 | T40: =+Q40-S40 -> 0
A41: 43131 | B41: =YEAR(A41) -> 2018 | C41: =MONTH(A41) -> 1 | D41: 181850 | E41: =+D41-D40 -> 190 | F41: =IF(E41>0,E41,0) -> 190 | G41: =MAX($D$34:D41) -> 181850 | I41: =MAX(0,+G41-G40) -> 190 | J41: =MIN(D41:D70) -> 180920 | K41: =MAX(0,+J41-J40) -> 0 | L41: =MIN(K41,F41-I41) -> 0 | M41: =+I41+L41 -> 190 | N41: =+F41-M41 -> 0 | O41: =MAX(0,IF(AND(I41=0,N41>0),0,O40+I41+S40)) -> 1120 | P41: =MAX(0,P40+N41+T40) -> 0 | Q41: =IF(E41<0,E41,0) -> 0 | R41: =MIN(0,+Q41+P40+T40) -> 0 | S41: =MAX(Q41,IF(O41>0,MAX(-O41,Q41),R41)) -> 0 | T41: =+Q41-S41 -> 0
A42: 43132 | B42: =YEAR(A42) -> 2018 | C42: =MONTH(A42) -> 2 | D42: 182140 | E42: =+D42-D41 -> 290 | F42: =IF(E42>0,E42,0) -> 290 | G42: =MAX($D$34:D42) -> 182140 | I42: =MAX(0,+G42-G41) -> 290 | J42: =MIN(D42:D71) -> 180920 | K42: =MAX(0,+J42-J41) -> 0 | L42: =MIN(K42,F42-I42) -> 0 | M42: =+I42+L42 -> 290 | N42: =+F42-M42 -> 0 | O42: =MAX(0,IF(AND(I42=0,N42>0),0,O41+I42+S41)) -> 1410 | P42: =MAX(0,P41+N42+T41) -> 0 | Q42: =IF(E42<0,E42,0) -> 0 | R42: =MIN(0,+Q42+P41+T41) -> 0 | S42: =MAX(Q42,IF(O42>0,MAX(-O42,Q42),R42)) -> 0 | T42: =+Q42-S42 -> 0
A43: 43133 | B43: =YEAR(A43) -> 2018 | C43: =MONTH(A43) -> 2 | D43: 182240 | E43: =+D43-D42 -> 100 | F43: =IF(E43>0,E43,0) -> 100 | G43: =MAX($D$34:D43) -> 182240 | I43: =MAX(0,+G43-G42) -> 100 | J43: =MIN(D43:D72) -> 180920 | K43: =MAX(0,+J43-J42) -> 0 | L43: =MIN(K43,F43-I43) -> 0 | M43: =+I43+L43 -> 100 | N43: =+F43-M43 -> 0 | O43: =MAX(0,IF(AND(I43=0,N43>0),0,O42+I43+S42)) -> 1510 | P43: =MAX(0,P42+N43+T42) -> 0 | Q43: =IF(E43<0,E43,0) -> 0 | R43: =MIN(0,+Q43+P42+T42) -> 0 | S43: =MAX(Q43,IF(O43>0,MAX(-O43,Q43),R43)) -> 0 | T43: =+Q43-S43 -> 0
A44: 43134 | B44: =YEAR(A44) -> 2018 | C44: =MONTH(A44) -> 2 | D44: 182160 | E44: =+D44-D43 -> -80 | F44: =IF(E44>0,E44,0) -> 0 | G44: =MAX($D$34:D44) -> 182240 | I44: =MAX(0,+G44-G43) -> 0 | J44: =MIN(D44:D73) -> 180920 | K44: =MAX(0,+J44-J43) -> 0 | L44: =MIN(K44,F44-I44) -> 0 | M44: =+I44+L44 -> 0 | N44: =+F44-M44 -> 0 | O44: =MAX(0,IF(AND(I44=0,N44>0),0,O43+I44+S43)) -> 1510 | P44: =MAX(0,P43+N44+T43) -> 0 | Q44: =IF(E44<0,E44,0) -> -80 | R44: =MIN(0,+Q44+P43+T43) -> -80 | S44: =MAX(Q44,IF(O44>0,MAX(-O44,Q44),R44)) -> -80 | T44: =+Q44-S44 -> 0
A45: 43135 | B45: =YEAR(A45) -> 2018 | C45: =MONTH(A45) -> 2 | D45: 181960 | E45: =+D45-D44 -> -200 | F45: =IF(E45>0,E45,0) -> 0 | G45: =MAX($D$34:D45) -> 182240 | I45: =MAX(0,+G45-G44) -> 0 | J45: =MIN(D45:D74) -> 180920 | K45: =MAX(0,+J45-J44) -> 0 | L45: =MIN(K45,F45-I45) -> 0 | M45: =+I45+L45 -> 0 | N45: =+F45-M45 -> 0 | O45: =MAX(0,IF(AND(I45=0,N45>0),0,O44+I45+S44)) -> 1430 | P45: =MAX(0,P44+N45+T44) -> 0 | Q45: =IF(E45<0,E45,0) -> -200 | R45: =MIN(0,+Q45+P44+T44) -> -200 | S45: =MAX(Q45,IF(O45>0,MAX(-O45,Q45),R45)) -> -200 | T45: =+Q45-S45 -> 0
A46: 43136 | B46: =YEAR(A46) -> 2018 | C46: =MONTH(A46) -> 2 | D46: 181620 | E46: =+D46-D45 -> -340 | F46: =IF(E46>0,E46,0) -> 0 | G46: =MAX($D$34:D46) -> 182240 | I46: =MAX(0,+G46-G45) -> 0 | J46: =MIN(D46:D75) -> 180920 | K46: =MAX(0,+J46-J45) -> 0 | L46: =MIN(K46,F46-I46) -> 0 | M46: =+I46+L46 -> 0 | N46: =+F46-M46 -> 0 | O46: =MAX(0,IF(AND(I46=0,N46>0),0,O45+I46+S45)) -> 1230 | P46: =MAX(0,P45+N46+T45) -> 0 | Q46: =IF(E46<0,E46,0) -> -340 | R46: =MIN(0,+Q46+P45+T45) -> -340 | S46: =MAX(Q46,IF(O46>0,MAX(-O46,Q46),R46)) -> -340 | T46: =+Q46-S46 -> 0
... A380: 43470 | B380: =YEAR(A380) -> 2019 | C380: =MONTH(A380) -> 1 | D380: 183350 | E380: =+D380-D379 -> -210 | F380: =IF(E380>0,E380,0) -> 0 | G380: =MAX($D$34:D380) -> 205690 | I380: =MAX(0,+G380-G379) -> 0 | J380: =MIN(D380:D409) -> 182620 | K380: =MAX(0,+J380-J379) -> 0 | L380: =MIN(K380,F380-I380) -> 0 | M380: =+I380+L380 -> 0 | N380: =+F380-M380 -> 0 | O380: =MAX(0,IF(AND(I380=0,N380>0),0,O379+I380+S379)) -> 0 | P380: =MAX(0,P379+N380+T379) -> 0 | Q380: =IF(E380<0,E380,0) -> -210 | R380: =MIN(0,+Q380+P379+T379) -> -210 | S380: =MAX(Q380,IF(O380>0,MAX(-O380,Q380),R380)) -> -210 | T380: =+Q380-S380 -> 0
A381: 43471 | B381: =YEAR(A381) -> 2019 | C381: =MONTH(A381) -> 1 | D381: 183330 | E381: =+D381-D380 -> -20 | F381: =IF(E381>0,E381,0) -> 0 | G381: =MAX($D$34:D381) -> 205690 | H381: <---- | I381: =MAX(0,+G381-G380) -> 0 | J381: =MIN(D381:D410) -> 182620 | K381: =MAX(0,+J381-J380) -> 0 | L381: =MIN(K381,F381-I381) -> 0 | M381: =+I381+L381 -> 0 | N381: =+F381-M381 -> 0 | O381: =MAX(0,IF(AND(I381=0,N381>0),0,O380+I381+S380)) -> 0 | P381: =MAX(0,P380+N381+T380) -> 0 | Q381: =IF(E381<0,E381,0) -> -20 | R381: =MIN(0,+Q381+P380+T380) -> -20 | S381: =MAX(Q381,IF(O381>0,MAX(-O381,Q381),R381)) -> -20 | T381: =+Q381-S381 -> 0
A382: 43472 | B382: =YEAR(A382) -> 2019 | C382: =MONTH(A382) -> 1 | D382: 183660 | E382: =+D382-D381 -> 330 | F382: =IF(E382>0,E382,0) -> 330 | G382: =MAX($D$34:D382) -> 205690 | I382: =MAX(0,+G382-G381) -> 0 | J382: =MIN(D382:D411) -> 182620 | K382: =MAX(0,+J382-J381) -> 0 | L382: =MIN(K382,F382-I382) -> 0 | M382: =+I382+L382 -> 0 | N382: =+F382-M382 -> 330 | O382: =MAX(0,IF(AND(I382=0,N382>0),0,O381+I382+S381)) -> 0 | P382: =MAX(0,P381+N382+T381) -> 330 | Q382: =IF(E382<0,E382,0) -> 0 | R382: =MIN(0,+Q382+P381+T381) -> 0 | S382: =MAX(Q382,IF(O382>0,MAX(-O382,Q382),R382)) -> 0 | T382: =+Q382-S382 -> 0
A383: 43473 | B383: =YEAR(A383) -> 2019 | C383: =MONTH(A383) -> 1 | D383: 184220 | E383: =+D383-D382 -> 560 | F383: =IF(E383>0,E383,0) -> 560 | G383: =MAX($D$34:D383) -> 205690 | I383: =MAX(0,+G383-G382) -> 0 | J383: =MIN(D383:D412) -> 182620 | K383: =MAX(0,+J383-J382) -> 0 | L383: =MIN(K383,F383-I383) -> 0 | M383: =+I383+L383 -> 0 | N383: =+F383-M383 -> 560 | O383: =MAX(0,IF(AND(I383=0,N383>0),0,O382+I383+S382)) -> 0 | P383: =MAX(0,P382+N383+T382) -> 890 | Q383: =IF(E383<0,E383,0) -> 0 | R383: =MIN(0,+Q383+P382+T382) -> 0 | S383: =MAX(Q383,IF(O383>0,MAX(-O383,Q383),R383)) -> 0 | T383: =+Q383-S383 -> 0
A384: 43474 | B384: =YEAR(A384) -> 2019 | C384: =MONTH(A384) -> 1 | D384: 184640 | E384: =+D384-D383 -> 420 | F384: =IF(E384>0,E384,0) -> 420 | G384: =MAX($D$34:D384) -> 205690 | I384: =MAX(0,+G384-G383) -> 0 | J384: =MIN(D384:D413) -> 182620 | K384: =MAX(0,+J384-J383) -> 0 | L384: =MIN(K384,F384-I384) -> 0 | M384: =+I384+L384 -> 0 | N384: =+F384-M384 -> 420 | O384: =MAX(0,IF(AND(I384=0,N384>0),0,O383+I384+S383)) -> 0 | P384: =MAX(0,P383+N384+T383) -> 1310 | Q384: =IF(E384<0,E384,0) -> 0 | R384: =MIN(0,+Q384+P383+T383) -> 0 | S384: =MAX(Q384,IF(O384>0,MAX(-O384,Q384),R384)) -> 0 | T384: =+Q384-S384 -> 0
...

Sheet C
A1: Reservoir B - Collection to Storage and Withdrawal from Storage (30-day rule)
D4: INPUT | E4: INPUT | I4: INPUT/Calc
A6: 1 | F6: 2 | G6: 3 | H6: 4 | I6: 4.1 | J6: 4.2 | K6: 5 | N6: 6 | O6: 7 | P6: 8 | S6: 9 | U6: 10 | V6: 11
A7: DATA | K7: Collection to Storage | S7: Withdrawal from Storage
A8: Date | B8: Year | C8: month | D8: P | E8: Reservoir B | F8: Reservoir B only | G8: Storage Change | H8: Storage Gain | I8: Moving Maximum from Starting Date | J8: check (starting date) | K8: Initial Collection to Storage | L8: Forward 30-day Moving Minimum | M8: +ΔS | N8: Refill Collection | O8: Total Collection to Storage | P8: Regulatory Collection to Storage | Q8: Cumulative Initial Collection between Reg Collections | R8: Remaining Cumulative Reg Collection | S8: Storage Loss | T8: WD | U8: WD from Storage | V8: Regulatory WD | X8: Manual Corrections
D9: (AF) | F9: (AF) | G9: (AF) | H9: (AF) | K9: (AF) | N9: (AF) | O9: (AF) | P9: (AF) | S9: (AF) | U9: (AF) | V9: (AF)
A10: 43100 | B10: =YEAR(A10) -> 2017 | C10: =MONTH(A10) -> 12 | E10: 303310 | F10: =+E10 -> 303310 | I10: =MAX($F$10:F10) -> 303310
A11: 43101 | B11: =YEAR(A11) -> 2018 | C11: =MONTH(A11) -> 1 | E11: 302740 | F11: =+E11 -> 302740 | G11: =+F11-F10 -> -570 | H11: =IF(G11>0,G11,0) -> 0 | I11: =MAX($F$10:F11) -> 303310 | K11: =MAX(0,+I11-I10) -> 0 | L11: =MIN(F11:F40) -> 299400 | M11: =MAX(0,+L11-L10) -> 299400 | N11: =MIN(M11,H11-K11) -> 0 | O11: =+K11+N11 -> 0 | P11: =+H11-O11 -> 0 | Q11: =MAX(0,IF(AND(K11=0,P11>0),0,Q10+K11+U10)) -> 0 | R11: =MAX(0,R10+P11+V10) -> 0 | S11: =IF(G11<0,G11,0) -> -570 | T11: =MIN(0,+S11+R10+V10) -> -570 | U11: =MAX(S11,IF(Q11>0,MAX(-Q11,S11),T11)) -> -570 | V11: =+S11-U11 -> 0
A12: 43102 | B12: =YEAR(A12) -> 2018 | C12: =MONTH(A12) -> 1 | E12: 302030 | F12: =+E12 -> 302030 | G12: =+F12-F11 -> -710 | H12: =IF(G12>0,G12,0) -> 0 | I12: =MAX($F$10:F12) -> 303310 | K12: =MAX(0,+I12-I11) -> 0 | L12: =MIN(F12:F41) -> 299400 | M12: =MAX(0,+L12-L11) -> 0 | N12: =MIN(M12,H12-K12) -> 0 | O12: =+K12+N12 -> 0 | P12: =+H12-O12 -> 0 | Q12: =MAX(0,IF(AND(K12=0,P12>0),0,Q11+K12+U11)) -> 0 | R12: =MAX(0,R11+P12+V11) -> 0 | S12: =IF(G12<0,G12,0) -> -710 | T12: =MIN(0,+S12+R11+V11) -> -710 | U12: =MAX(S12,IF(Q12>0,MAX(-Q12,S12),T12)) -> -710 | V12: =+S12-U12 -> 0
A13: 43103 | B13: =YEAR(A13) -> 2018 | C13: =MONTH(A13) -> 1 | E13: 301770 | F13: =+E13 -> 301770 | G13: =+F13-F12 -> -260 | H13: =IF(G13>0,G13,0) -> 0 | I13: =MAX($F$10:F13) -> 303310 | K13: =MAX(0,+I13-I12) -> 0 | L13: =MIN(F13:F42) -> 299400 | M13: =MAX(0,+L13-L12) -> 0 | N13: =MIN(M13,H13-K13) -> 0 | O13: =+K13+N13 -> 0 | P13: =+H13-O13 -> 0 | Q13: =MAX(0,IF(AND(K13=0,P13>0),0,Q12+K13+U12)) -> 0 | R13: =MAX(0,R12+P13+V12) -> 0 | S13: =IF(G13<0,G13,0) -> -260 | T13: =MIN(0,+S13+R12+V12) -> -260 | U13: =MAX(S13,IF(Q13>0,MAX(-Q13,S13),T13)) -> -260 | V13: =+S13-U13 -> 0
A14: 43104 | B14: =YEAR(A14) -> 2018 | C14: =MONTH(A14) -> 1 | E14: 301130 | F14: =+E14 -> 301130 | G14: =+F14-F13 -> -640 | H14: =IF(G14>0,G14,0) -> 0 | I14: =MAX($F$10:F14) -> 303310 | K14: =MAX(0,+I14-I13) -> 0 | L14: =MIN(F14:F43) -> 299400 | M14: =MAX(0,+L14-L13) -> 0 | N14: =MIN(M14,H14-K14) -> 0 | O14: =+K14+N14 -> 0 | P14: =+H14-O14 -> 0 | Q14: =MAX(0,IF(AND(K14=0,P14>0),0,Q13+K14+U13)) -> 0 | R14: =MAX(0,R13+P14+V13) -> 0 | S14: =IF(G14<0,G14,0) -> -640 | T14: =MIN(0,+S14+R13+V13) -> -640 | U14: =MAX(S14,IF(Q14>0,MAX(-Q14,S14),T14)) -> -640 | V14: =+S14-U14 -> 0
A15: 43105 | B15: =YEAR(A15) -> 2018 | C15: =MONTH(A15) -> 1 | E15: 300490 | F15: =+E15 -> 300490 | G15: =+F15-F14 -> -640 | H15: =IF(G15>0,G15,0) -> 0 | I15: =MAX($F$10:F15) -> 303310 | K15: =MAX(0,+I15-I14) -> 0 | L15: =MIN(F15:F44) -> 299400 | M15: =MAX(0,+L15-L14) -> 0 | N15: =MIN(M15,H15-K15) -> 0 | O15: =+K15+N15 -> 0 | P15: =+H15-O15 -> 0 | Q15: =MAX(0,IF(AND(K15=0,P15>0),0,Q14+K15+U14)) -> 0 | R15: =MAX(0,R14+P15+V14) -> 0 | S15: =IF(G15<0,G15,0) -> -640 | T15: =MIN(0,+S15+R14+V14) -> -640 | U15: =MAX(S15,IF(Q15>0,MAX(-Q15,S15),T15)) -> -640 | V15: =+S15-U15 -> 0
A16: 43106 | B16: =YEAR(A16) -> 2018 | C16: =MONTH(A16) -> 1 | E16: 299970 | F16: =+E16 -> 299970 | G16: =+F16-F15 -> -520 | H16: =IF(G16>0,G16,0) -> 0 | I16: =MAX($F$10:F16) -> 303310 | K16: =MAX(0,+I16-I15) -> 0 | L16: =MIN(F16:F45) -> 299400 | M16: =MAX(0,+L16-L15) -> 0 | N16: =MIN(M16,H16-K16) -> 0 | O16: =+K16+N16 -> 0 | P16: =+H16-O16 -> 0 | Q16: =MAX(0,IF(AND(K16=0,P16>0),0,Q15+K16+U15)) -> 0 | R16: =MAX(0,R15+P16+V15) -> 0 | S16: =IF(G16<0,G16,0) -> -520 | T16: =MIN(0,+S16+R15+V15) -> -520 | U16: =MAX(S16,IF(Q16>0,MAX(-Q16,S16),T16)) -> -520 | V16: =+S16-U16 -> 0
A17: 43107 | B17: =YEAR(A17) -> 2018 | C17: =MONTH(A17) -> 1 | E17: 299400 | F17: =+E17 -> 299400 | G17: =+F17-F16 -> -570 | H17: =IF(G17>0,G17,0) -> 0 | I17: =MAX($F$10:F17) -> 303310 | K17: =MAX(0,+I17-I16) -> 0 | L17: =MIN(F17:F46) -> 299400 | M17: =MAX(0,+L17-L16) -> 0 | N17: =MIN(M17,H17-K17) -> 0 | O17: =+K17+N17 -> 0 | P17: =+H17-O17 -> 0 | Q17: =MAX(0,IF(AND(K17=0,P17>0),0,Q16+K17+U16)) -> 0 | R17: =MAX(0,R16+P17+V16) -> 0 | S17: =IF(G17<0,G17,0) -> -570 | T17: =MIN(0,+S17+R16+V16) -> -570 | U17: =MAX(S17,IF(Q17>0,MAX(-Q17,S17),T17)) -> -570 | V17: =+S17-U17 -> 0
A18: 43108 | B18: =YEAR(A18) -> 2018 | C18: =MONTH(A18) -> 1 | E18: 300810 | F18: =+E18 -> 300810 | G18: =+F18-F17 -> 1410 | H18: =IF(G18>0,G18,0) -> 1410 | I18: =MAX($F$10:F18) -> 303310 | K18: =MAX(0,+I18-I17) -> 0 | L18: =MIN(F18:F47) -> 300810 | M18: =MAX(0,+L18-L17) -> 1410 | N18: =MIN(M18,H18-K18) -> 1410 | O18: =+K18+N18 -> 1410 | P18: =+H18-O18 -> 0 | Q18: =MAX(0,IF(AND(K18=0,P18>0),0,Q17+K18+U17)) -> 0 | R18: =MAX(0,R17+P18+V17) -> 0 | S18: =IF(G18<0,G18,0) -> 0 | T18: =MIN(0,+S18+R17+V17) -> 0 | U18: =MAX(S18,IF(Q18>0,MAX(-Q18,S18),T18)) -> 0 | V18: =+S18-U18 -> 0
A19: 43109 | B19: =YEAR(A19) -> 2018 | C19: =MONTH(A19) -> 1 | E19: 302160 | F19: =+E19 -> 302160 | G19: =+F19-F18 -> 1350 | H19: =IF(G19>0,G19,0) -> 1350 | I19: =MAX($F$10:F19) -> 303310 | K19: =MAX(0,+I19-I18) -> 0 | L19: =MIN(F19:F48) -> 302160 | M19: =MAX(0,+L19-L18) -> 1350 | N19: =MIN(M19,H19-K19) -> 1350 | O19: =+K19+N19 -> 1350 | P19: =+H19-O19 -> 0 | Q19: =MAX(0,IF(AND(K19=0,P19>0),0,Q18+K19+U18)) -> 0 | R19: =MAX(0,R18+P19+V18) -> 0 | S19: =IF(G19<0,G19,0) -> 0 | T19: =MIN(0,+S19+R18+V18) -> 0 | U19: =MAX(S19,IF(Q19>0,MAX(-Q19,S19),T19)) -> 0 | V19: =+S19-U19 -> 0
A20: 43110 | B20: =YEAR(A20) -> 2018 | C20: =MONTH(A20) -> 1 | E20: 303890 | F20: =+E20 -> 303890 | G20: =+F20-F19 -> 1730 | H20: =IF(G20>0,G20,0) -> 1730 | I20: =MAX($F$10:F20) -> 303890 | K20: =MAX(0,+I20-I19) -> 580 | L20: =MIN(F20:F49) -> 303890 | M20: =MAX(0,+L20-L19) -> 1730 | N20: =MIN(M20,H20-K20) -> 1150 | O20: =+K20+N20 -> 1730 | P20: =+H20-O20 -> 0 | Q20: =MAX(0,IF(AND(K20=0,P20>0),0,Q19+K20+U19)) -> 580 | R20: =MAX(0,R19+P20+V19) -> 0 | S20: =IF(G20<0,G20,0) -> 0 | T20: =MIN(0,+S20+R19+V19) -> 0 | U20: =MAX(S20,IF(Q20>0,MAX(-Q20,S20),T20)) -> 0 | V20: =+S20-U20 -> 0
A21: 43111 | B21: =YEAR(A21) -> 2018 | C21: =MONTH(A21) -> 1 | E21: 305050 | F21: =+E21 -> 305050 | G21: =+F21-F20 -> 1160 | H21: =IF(G21>0,G21,0) -> 1160 | I21: =MAX($F$10:F21) -> 305050 | K21: =MAX(0,+I21-I20) -> 1160 | L21: =MIN(F21:F50) -> 305050 | M21: =MAX(0,+L21-L20) -> 1160 | N21: =MIN(M21,H21-K21) -> 0 | O21: =+K21+N21 -> 1160 | P21: =+H21-O21 -> 0 | Q21: =MAX(0,IF(AND(K21=0,P21>0),0,Q20+K21+U20)) -> 1740 | R21: =MAX(0,R20+P21+V20) -> 0 | S21: =IF(G21<0,G21,0) -> 0 | T21: =MIN(0,+S21+R20+V20) -> 0 | U21: =MAX(S21,IF(Q21>0,MAX(-Q21,S21),T21)) -> 0 | V21: =+S21-U21 -> 0
A22: 43112 | B22: =YEAR(A22) -> 2018 | C22: =MONTH(A22) -> 1 | E22: 306350 | F22: =+E22 -> 306350 | G22: =+F22-F21 -> 1300 | H22: =IF(G22>0,G22,0) -> 1300 | I22: =MAX($F$10:F22) -> 306350 | K22: =MAX(0,+I22-I21) -> 1300 | L22: =MIN(F22:F51) -> 306350 | M22: =MAX(0,+L22-L21) -> 1300 | N22: =MIN(M22,H22-K22) -> 0 | O22: =+K22+N22 -> 1300 | P22: =+H22-O22 -> 0 | Q22: =MAX(0,IF(AND(K22=0,P22>0),0,Q21+K22+U21)) -> 3040 | R22: =MAX(0,R21+P22+V21) -> 0 | S22: =IF(G22<0,G22,0) -> 0 | T22: =MIN(0,+S22+R21+V21) -> 0 | U22: =MAX(S22,IF(Q22>0,MAX(-Q22,S22),T22)) -> 0 | V22: =+S22-U22 -> 0
... A66: 43156 | B66: =YEAR(A66) -> 2018 | C66: =MONTH(A66) -> 2 | E66: 304410 | F66: =+E66 -> 304410 | G66: =+F66-F65 -> -640 | H66: =IF(G66>0,G66,0) -> 0 | I66: =MAX($F$10:F66) -> 317760 | K66: =MAX(0,+I66-I65) -> 0 | L66: =MIN(F66:F95) -> 298250 | M66: =MAX(0,+L66-L65) -> 0 | N66: =MIN(M66,H66-K66) -> 0 | O66: =+K66+N66 -> 0 | P66: =+H66-O66 -> 0 | Q66: =MAX(0,IF(AND(K66=0,P66>0),0,Q65+K66+U65)) -> 1740 | R66: =MAX(0,R65+P66+V65) -> 0 | S66: =IF(G66<0,G66,0) -> -640 | T66: =MIN(0,+S66+R65+V65) -> -640 | U66: =MAX(S66,IF(Q66>0,MAX(-Q66,S66),T66)) -> -640 | V66: =+S66-U66 -> 0
A67: 43157 | B67: =YEAR(A67) -> 2018 | C67: =MONTH(A67) -> 2 | E67: 303960 | F67: =+E67 -> 303960 | G67: =+F67-F66 -> -450 | H67: =IF(G67>0,G67,0) -> 0 | I67: =MAX($F$10:F67) -> 317760 | K67: =MAX(0,+I67-I66) -> 0 | L67: =MIN(F67:F96) -> 298250 | M67: =MAX(0,+L67-L66) -> 0 | N67: =MIN(M67,H67-K67) -> 0 | O67: =+K67+N67 -> 0 | P67: =+H67-O67 -> 0 | Q67: =MAX(0,IF(AND(K67=0,P67>0),0,Q66+K67+U66)) -> 1100 | R67: =MAX(0,R66+P67+V66) -> 0 | S67: =IF(G67<0,G67,0) -> -450 | T67: =MIN(0,+S67+R66+V66) -> -450 | U67: -450 | V67: =+S67-U67 -> 0
A68: 43158 | B68: =YEAR(A68) -> 2018 | C68: =MONTH(A68) -> 2 | E68: 303310 | F68: =+E68 -> 303310 | G68: =+F68-F67 -> -650 | H68: =IF(G68>0,G68,0) -> 0 | I68: =MAX($F$10:F68) -> 317760 | K68: =MAX(0,+I68-I67) -> 0 | L68: =MIN(F68:F97) -> 298250 | M68: =MAX(0,+L68-L67) -> 0 | N68: =MIN(M68,H68-K68) -> 0 | O68: =+K68+N68 -> 0 | P68: =+H68-O68 -> 0 | Q68: =MAX(0,IF(AND(K68=0,P68>0),0,Q67+K68+U67)) -> 650 | R68: =MAX(0,R67+P68+V67) -> 0 | S68: =IF(G68<0,G68,0) -> -650 | T68: =MIN(0,+S68+R67+V67) -> -650 | U68: =MAX(S68,IF(Q68>0,MAX(-Q68,S68),T68)) -> -650 | V68: =+S68-U68 -> 0
A69: 43159 | B69: =YEAR(A69) -> 2018 | C69: =MONTH(A69) -> 2 | E69: 302800 | F69: =+E69 -> 302800 | G69: =+F69-F68 -> -510 | H69: =IF(G69>0,G69,0) -> 0 | I69: =MAX($F$10:F69) -> 317760 | K69: =MAX(0,+I69-I68) -> 0 | L69: =MIN(F69:F98) -> 298250 | M69: =MAX(0,+L69-L68) -> 0 | N69: =MIN(M69,H69-K69) -> 0 | O69: =+K69+N69 -> 0 | P69: =+H69-O69 -> 0 | Q69: =MAX(0,IF(AND(K69=0,P69>0),0,Q68+K69+U68)) -> 0 | R69: =MAX(0,R68+P69+V68) -> 0 | S69: =IF(G69<0,G69,0) -> -510 | T69: =MIN(0,+S69+R68+V68) -> -510 | U69: =MAX(S69,IF(Q69>0,MAX(-Q69,S69),T69)) -> -510 | V69: =+S69-U69 -> 0
A70: 43160 | B70: =YEAR(A70) -> 2018 | C70: =MONTH(A70) -> 3 | E70: 302410 | F70: =+E70 -> 302410 | G70: =+F70-F69 -> -390 | H70: =IF(G70>0,G70,0) -> 0 | I70: =MAX($F$10:F70) -> 317760 | K70: =MAX(0,+I70-I69) -> 0 | L70: =MIN(F70:F99) -> 298250 | M70: =MAX(0,+L70-L69) -> 0 | N70: =MIN(M70,H70-K70) -> 0 | O70: =+K70+N70 -> 0 | P70: =+H70-O70 -> 0 | Q70: =MAX(0,IF(AND(K70=0,P70>0),0,Q69+K70+U69)) -> 0 | R70: =MAX(0,R69+P70+V69) -> 0 | S70: =IF(G70<0,G70,0) -> -390 | T70: =MIN(0,+S70+R69+V69) -> -390 | U70: =MAX(S70,IF(Q70>0,MAX(-Q70,S70),T70)) -> -390 | V70: =+S70-U70 -> 0
A71: 43161 | B71: =YEAR(A71) -> 2018 | C71: =MONTH(A71) -> 3 | E71: 302160 | F71: =+E71 -> 302160 | G71: =+F71-F70 -> -250 | H71: =IF(G71>0,G71,0) -> 0 | I71: =MAX($F$10:F71) -> 317760 | K71: =MAX(0,+I71-I70) -> 0 | L71: =MIN(F71:F100) -> 298250 | M71: =MAX(0,+L71-L70) -> 0 | N71: =MIN(M71,H71-K71) -> 0 | O71: =+K71+N71 -> 0 | P71: =+H71-O71 -> 0 | Q71: =MAX(0,IF(AND(K71=0,P71>0),0,Q70+K71+U70)) -> 0 | R71: =MAX(0,R70+P71+V70) -> 0 | S71: =IF(G71<0,G71,0) -> -250 | T71: =MIN(0,+S71+R70+V70) -> -250 | U71: =MAX(S71,IF(Q71>0,MAX(-Q71,S71),T71)) -> -250 | V71: =+S71-U71 -> 0
A72: 43162 | B72: =YEAR(A72) -> 2018 | C72: =MONTH(A72) -> 3 | E72: 301770 | F72: =+E72 -> 301770 | G72: =+F72-F71 -> -390 | H72: =IF(G72>0,G72,0) -> 0 | I72: =MAX($F$10:F72) -> 317760 | K72: =MAX(0,+I72-I71) -> 0 | L72: =MIN(F72:F101) -> 298250 | M72: =MAX(0,+L72-L71) -> 0 | N72: =MIN(M72,H72-K72) -> 0 | O72: =+K72+N72 -> 0 | P72: =+H72-O72 -> 0 | Q72: =MAX(0,IF(AND(K72=0,P72>0),0,Q71+K72+U71)) -> 0 | R72: =MAX(0,R71+P72+V71) -> 0 | S72: =IF(G72<0,G72,0) -> -390 | T72: =MIN(0,+S72+R71+V71) -> -390 | U72: =MAX(S72,IF(Q72>0,MAX(-Q72,S72),T72)) -> -390 | V72: =+S72-U72 -> 0
A73: 43163 | B73: =YEAR(A73) -> 2018 | C73: =MONTH(A73) -> 3 | E73: 301060 | F73: =+E73 -> 301060 | G73: =+F73-F72 -> -710 | H73: =IF(G73>0,G73,0) -> 0 | I73: =MAX($F$10:F73) -> 317760 | K73: =MAX(0,+I73-I72) -> 0 | L73: =MIN(F73:F102) -> 298250 | M73: =MAX(0,+L73-L72) -> 0 | N73: =MIN(M73,H73-K73) -> 0 | O73: =+K73+N73 -> 0 | P73: =+H73-O73 -> 0 | Q73: =MAX(0,IF(AND(K73=0,P73>0),0,Q72+K73+U72)) -> 0 | R73: =MAX(0,R72+P73+V72) -> 0 | S73: =IF(G73<0,G73,0) -> -710 | T73: =MIN(0,+S73+R72+V72) -> -710 | U73: =MAX(S73,IF(Q73>0,MAX(-Q73,S73),T73)) -> -710 | V73: =+S73-U73 -> 0
A74: 43164 | B74: =YEAR(A74) -> 2018 | C74: =MONTH(A74) -> 3 | E74: 300420 | F74: =+E74 -> 300420 | G74: =+F74-F73 -> -640 | H74: =IF(G74>0,G74,0) -> 0 | I74: =MAX($F$10:F74) -> 317760 | K74: =MAX(0,+I74-I73) -> 0 | L74: =MIN(F74:F103) -> 298250 | M74: =MAX(0,+L74-L73) -> 0 | N74: =MIN(M74,H74-K74) -> 0 | O74: =+K74+N74 -> 0 | P74: =+H74-O74 -> 0 | Q74: =MAX(0,IF(AND(K74=0,P74>0),0,Q73+K74+U73)) -> 0 | R74: =MAX(0,R73+P74+V73) -> 0 | S74: =IF(G74<0,G74,0) -> -640 | T74: =MIN(0,+S74+R73+V73) -> -640 | U74: =MAX(S74,IF(Q74>0,MAX(-Q74,S74),T74)) -> -640 | V74: =+S74-U74 -> 0
A75: 43165 | B75: =YEAR(A75) -> 2018 | C75: =MONTH(A75) -> 3 | E75: 299780 | F75: =+E75 -> 299780 | G75: =+F75-F74 -> -640 | H75: =IF(G75>0,G75,0) -> 0 | I75: =MAX($F$10:F75) -> 317760 | K75: =MAX(0,+I75-I74) -> 0 | L75: =MIN(F75:F104) -> 298250 | M75: =MAX(0,+L75-L74) -> 0 | N75: =MIN(M75,H75-K75) -> 0 | O75: =+K75+N75 -> 0 | P75: =+H75-O75 -> 0 | Q75: =MAX(0,IF(AND(K75=0,P75>0),0,Q74+K75+U74)) -> 0 | R75: =MAX(0,R74+P75+V74) -> 0 | S75: =IF(G75<0,G75,0) -> -640 | T75: =MIN(0,+S75+R74+V74) -> -640 | U75: =MAX(S75,IF(Q75>0,MAX(-Q75,S75),T75)) -> -640 | V75: =+S75-U75 -> 0
A76: 43166 | B76: =YEAR(A76) -> 2018 | C76: =MONTH(A76) -> 3 | E76: 299020 | F76: =+E76 -> 299020 | G76: =+F76-F75 -> -760 | H76: =IF(G76>0,G76,0) -> 0 | I76: =MAX($F$10:F76) -> 317760 | K76: =MAX(0,+I76-I75) -> 0 | L76: =MIN(F76:F105) -> 298250 | M76: =MAX(0,+L76-L75) -> 0 | N76: =MIN(M76,H76-K76) -> 0 | O76: =+K76+N76 -> 0 | P76: =+H76-O76 -> 0 | Q76: =MAX(0,IF(AND(K76=0,P76>0),0,Q75+K76+U75)) -> 0 | R76: =MAX(0,R75+P76+V75) -> 0 | S76: =IF(G76<0,G76,0) -> -760 | T76: =MIN(0,+S76+R75+V75) -> -760 | U76: =MAX(S76,IF(Q76>0,MAX(-Q76,S76),T76)) -> -760 | V76: =+S76-U76 -> 0
A77: 43167 | B77: =YEAR(A77) -> 2018 | C77: =MONTH(A77) -> 3 | E77: 298700 | F77: =+E77 -> 298700 | G77: =+F77-F76 -> -320 | H77: =IF(G77>0,G77,0) -> 0 | I77: =MAX($F$10:F77) -> 317760 | K77: =MAX(0,+I77-I76) -> 0 | L77: =MIN(F77:F106) -> 298250 | M77: =MAX(0,+L77-L76) -> 0 | N77: =MIN(M77,H77-K77) -> 0 | O77: =+K77+N77 -> 0 | P77: =+H77-O77 -> 0 | Q77: =MAX(0,IF(AND(K77=0,P77>0),0,Q76+K77+U76)) -> 0 | R77: =MAX(0,R76+P77+V76) -> 0 | S77: =IF(G77<0,G77,0) -> -320 | T77: =MIN(0,+S77+R76+V76) -> -320 | U77: =MAX(S77,IF(Q77>0,MAX(-Q77,S77),T77)) -> -320 | V77: =+S77-U77 -> 0
A78: 43168 | B78: =YEAR(A78) -> 2018 | C78: =MONTH(A78) -> 3 | E78: 298500 | F78: =+E78 -> 298500 | G78: =+F78-F77 -> -200 | H78: =IF(G78>0,G78,0) -> 0 | I78: =MAX($F$10:F78) -> 317760 | K78: =MAX(0,+I78-I77) -> 0 | L78: =MIN(F78:F107) -> 298250 | M78: =MAX(0,+L78-L77) -> 0 | N78: =MIN(M78,H78-K78) -> 0 | O78: =+K78+N78 -> 0 | P78: =+H78-O78 -> 0 | Q78: =MAX(0,IF(AND(K78=0,P78>0),0,Q77+K78+U77)) -> 0 | R78: =MAX(0,R77+P78+V77) -> 0 | S78: =IF(G78<0,G78,0) -> -200 | T78: =MIN(0,+S78+R77+V77) -> -200 | U78: =MAX(S78,IF(Q78>0,MAX(-Q78,S78),T78)) -> -200 | V78: =+S78-U78 -> 0
A79: 43169 | B79: =YEAR(A79) -> 2018 | C79: =MONTH(A79) -> 3 | E79: 298250 | F79: =+E79 -> 298250 | G79: =+F79-F78 -> -250 | H79: =IF(G79>0,G79,0) -> 0 | I79: =MAX($F$10:F79) -> 317760 | K79: =MAX(0,+I79-I78) -> 0 | L79: =MIN(F79:F108) -> 298250 | M79: =MAX(0,+L79-L78) -> 0 | N79: =MIN(M79,H79-K79) -> 0 | O79: =+K79+N79 -> 0 | P79: =+H79-O79 -> 0 | Q79: =MAX(0,IF(AND(K79=0,P79>0),0,Q78+K79+U78)) -> 0 | R79: =MAX(0,R78+P79+V78) -> 0 | S79: =IF(G79<0,G79,0) -> -250 | T79: =MIN(0,+S79+R78+V78) -> -250 | U79: =MAX(S79,IF(Q79>0,MAX(-Q79,S79),T79)) -> -250 | V79: =+S79-U79 -> 0
... A346: 43436 | B346: =YEAR(A346) -> 2018 | C346: =MONTH(A346) -> 12 | E346: 296400 | F346: =+E346 -> 296400 | G346: =+F346-F345 -> -450 | H346: =IF(G346>0,G346,0) -> 0 | I346: =MAX($F$10:F346) -> 391480 | K346: =MAX(0,+I346-I345) -> 0 | L346: =MIN(F346:F375) -> 296270 | M346: =MAX(0,+L346-L345) -> 0 | N346: =MIN(M346,H346-K346) -> 0 | O346: =+K346+N346 -> 0 | P346: =+H346-O346 -> 0 | Q346: =MAX(0,IF(AND(K346=0,P346>0),0,Q345+K346+U345)) -> 0 | R346: =MAX(0,R345+P346+V345) -> 0 | S346: =IF(G346<0,G346,0) -> -450 | T346: =MIN(0,+S346+R345+V345) -> -450 | U346: =MAX(S346,IF(Q346>0,MAX(-Q346,S346),T346)) -> -450 | V346: =+S346-U346 -> 0
A347: 43437 | B347: =YEAR(A347) -> 2018 | C347: =MONTH(A347) -> 12 | E347: 296270 | F347: =+E347 -> 296270 | G347: =+F347-F346 -> -130 | H347: =IF(G347>0,G347,0) -> 0 | I347: =MAX($F$347:F347) -> 296270 | J347: <--- | K347: =MAX(0,+I347-I346) -> 0 | L347: =MIN(F347:F376) -> 296270 | M347: =MAX(0,+L347-L346) -> 0 | N347: =MIN(M347,H347-K347) -> 0 | O347: =+K347+N347 -> 0 | P347: =+H347-O347 -> 0 | Q347: =MAX(0,IF(AND(K347=0,P347>0),0,Q346+K347+U346)) -> 0 | R347: =MAX(0,R346+P347+V346) -> 0 | S347: =IF(G347<0,G347,0) -> -130 | T347: =MIN(0,+S347+R346+V346) -> -130 | U347: =MAX(S347,IF(Q347>0,MAX(-Q347,S347),T347)) -> -130 | V347: =+S347-U347 -> 0
A348: 43438 | B348: =YEAR(A348) -> 2018 | C348: =MONTH(A348) -> 12 | E348: 296850 | F348: =+E348 -> 296850 | G348: =+F348-F347 -> 580 | H348: =IF(G348>0,G348,0) -> 580 | I348: =MAX($F$347:F348) -> 296850 | K348: =MAX(0,+I348-I347) -> 580 | L348: =MIN(F348:F377) -> 296850 | M348: =MAX(0,+L348-L347) -> 580 | N348: =MIN(M348,H348-K348) -> 0 | O348: =+K348+N348 -> 580 | P348: =+H348-O348 -> 0 | Q348: =MAX(0,IF(AND(K348=0,P348>0),0,Q347+K348+U347)) -> 450 | R348: =MAX(0,R347+P348+V347) -> 0 | S348: =IF(G348<0,G348,0) -> 0 | T348: =MIN(0,+S348+R347+V347) -> 0 | U348: =MAX(S348,IF(Q348>0,MAX(-Q348,S348),T348)) -> 0 | V348: =+S348-U348 -> 0
A349: 43439 | B349: =YEAR(A349) -> 2018 | C349: =MONTH(A349) -> 12 | E349: 297800 | F349: =+E349 -> 297800 | G349: =+F349-F348 -> 950 | H349: =IF(G349>0,G349,0) -> 950 | I349: =MAX($F$347:F349) -> 297800 | K349: =MAX(0,+I349-I348) -> 950 | L349: =MIN(F349:F378) -> 297800 | M349: =MAX(0,+L349-L348) -> 950 | N349: =MIN(M349,H349-K349) -> 0 | O349: =+K349+N349 -> 950 | P349: =+H349-O349 -> 0 | Q349: =MAX(0,IF(AND(K349=0,P349>0),0,Q348+K349+U348)) -> 1400 | R349: =MAX(0,R348+P349+V348) -> 0 | S349: =IF(G349<0,G349,0) -> 0 | T349: =MIN(0,+S349+R348+V348) -> 0 | U349: =MAX(S349,IF(Q349>0,MAX(-Q349,S349),T349)) -> 0 | V349: =+S349-U349 -> 0
A350: 43440 | B350: =YEAR(A350) -> 2018 | C350: =MONTH(A350) -> 12 | E350: 298630 | F350: =+E350 -> 298630 | G350: =+F350-F349 -> 830 | H350: =IF(G350>0,G350,0) -> 830 | I350: =MAX($F$347:F350) -> 298630 | K350: =MAX(0,+I350-I349) -> 830 | L350: =MIN(F350:F379) -> 298630 | M350: =MAX(0,+L350-L349) -> 830 | N350: =MIN(M350,H350-K350) -> 0 | O350: =+K350+N350 -> 830 | P350: =+H350-O350 -> 0 | Q350: =MAX(0,IF(AND(K350=0,P350>0),0,Q349+K350+U349)) -> 2230 | R350: =MAX(0,R349+P350+V349) -> 0 | S350: =IF(G350<0,G350,0) -> 0 | T350: =MIN(0,+S350+R349+V349) -> 0 | U350: =MAX(S350,IF(Q350>0,MAX(-Q350,S350),T350)) -> 0 | V350: =+S350-U350 -> 0
A351: 43441 | B351: =YEAR(A351) -> 2018 | C351: =MONTH(A351) -> 12 | E351: 299460 | F351: =+E351 -> 299460 | G351: =+F351-F350 -> 830 | H351: =IF(G351>0,G351,0) -> 830 | I351: =MAX($F$347:F351) -> 299460 | K351: =MAX(0,+I351-I350) -> 830 | L351: =MIN(F351:F380) -> 299460 | M351: =MAX(0,+L351-L350) -> 830 | N351: =MIN(M351,H351-K351) -> 0 | O351: =+K351+N351 -> 830 | P351: =+H351-O351 -> 0 | Q351: =MAX(0,IF(AND(K351=0,P351>0),0,Q350+K351+U350)) -> 3060 | R351: =MAX(0,R350+P351+V350) -> 0 | S351: =IF(G351<0,G351,0) -> 0 | T351: =MIN(0,+S351+R350+V350) -> 0 | U351: =MAX(S351,IF(Q351>0,MAX(-Q351,S351),T351)) -> 0 | V351: =+S351-U351 -> 0
A352: 43442 | B352: =YEAR(A352) -> 2018 | C352: =MONTH(A352) -> 12 | E352: 299970 | F352: =+E352 -> 299970 | G352: =+F352-F351 -> 510 | H352: =IF(G352>0,G352,0) -> 510 | I352: =MAX($F$347:F352) -> 299970 | K352: =MAX(0,+I352-I351) -> 510 | L352: =MIN(F352:F381) -> 299970 | M352: =MAX(0,+L352-L351) -> 510 | N352: =MIN(M352,H352-K352) -> 0 | O352: =+K352+N352 -> 510 | P352: =+H352-O352 -> 0 | Q352: =MAX(0,IF(AND(K352=0,P352>0),0,Q351+K352+U351)) -> 3570 | R352: =MAX(0,R351+P352+V351) -> 0 | S352: =IF(G352<0,G352,0) -> 0 | T352: =MIN(0,+S352+R351+V351) -> 0 | U352: =MAX(S352,IF(Q352>0,MAX(-Q352,S352),T352)) -> 0 | V352: =+S352-U352 -> 0
...

Sheet P+C
A1: Reservoir A+B - Collection to Storage and Withdrawal from Storage (30-day rule)
K2: 68150 | L2: 184570080 | M2: 72550 | N2: 15800 | O2: 83950 | P2: 6210
K3: =SUM(K2475:K2843) -> 67120 | L3: =SUM(L2475:L2843) -> 184570080 | M3: =SUM(M2475:M2843) -> 72550 | N3: =SUM(N2475:N2843) -> 15950 | O3: =SUM(O2475:O2843) -> 83070 | P3: =SUM(P2475:P2843) -> 7090 | U3: =SUM(U2475:U2843) -> -129390 | V3: =SUM(V2475:V2843) -> -7090
D4: INPUT/Link | E4: INPUT/Link | I4: INPUT/Calc
O5: For Water Rts Reports | U5: For Water Rts Reports
A6: 1 | F6: 2 | H6: 4 | I6: 4.1 | J6: 4.2 | K6: 5 | N6: 6 | O6: 7 | P6: 8 | S6: 9 | U6: 10 | V6: 11
A7: DATA | K7: Collection to Storage | S7: Withdrawal from Storage
A8: Date | B8: Year | C8: month | D8: =P!D8 -> Reservoir A | E8: ='C'!E8 -> Reservoir B | F8: Reservoir A+B | G8: A+B Storage Change | H8: A+B Storage Gain | I8: Moving Maximum from Starting Date | J8: check (starting date) | K8: Initial Collection to Storage | L8: Forward 30-day Moving Minimum | M8: +ΔS | N8: Refill Collection | O8: Total Collection to Storage | P8: Regulatory Collection to Storage | Q8: Cumulative Initial Collection between Reg Collections | R8: Remaining Cumulative Reg Collection | S8: Storage Loss | T8: WD | U8: WD from Storage | V8: Regulatory WD | X8: Manual Corrections
D9: (AF) | F9: (AF) | G9: (AF) | H9: (AF) | K9: (AF) | N9: (AF) | O9: (AF) | P9: (AF) | S9: (AF) | U9: (AF) | V9: (AF)
A10: 43100 | D10: 192770 | E10: 303310 | F10: =+D10+E10 -> 496080
A11: =+A10+1 -> 43101 | B11: =YEAR(A11) -> 2018 | C11: =MONTH(A11) -> 1 | D11: =+P!D11 -> 193200 | E11: ='C'!E11 -> 302740 | F11: =+D11+E11 -> 495940 | G11: =+F11-F10 -> -140 | H11: =IF(G11>0,G11,0) -> 0 | I11: =MAX($F$10:F11) -> 496080 | L11: =MIN(F11:F40) -> 495750 | M11: =MAX(0,+L11-L10) -> 495750 | N11: =MIN(M11,H11-K11) -> 0 | O11: =+K11+N11 -> 0 | P11: =+H11-O11 -> 0 | Q11: =MAX(0,IF(AND(K11=0,P11>0),0,Q10+K11+U10)) -> 0 | R11: =MAX(0,R10+P11+V10) -> 0 | S11: =IF(G11<0,G11,0) -> -140 | T11: =MIN(0,+S11+R10+V10) -> -140 | U11: =MAX(S11,IF(Q11>0,MAX(-Q11,S11),T11)) -> -140 | V11: =+S11-U11 -> 0 | Y11: =P!M11 -> 430 | Z11: =MAX(O11-Y11,0) -> 0
A12: =+A11+1 -> 43102 | B12: =YEAR(A12) -> 2018 | C12: =MONTH(A12) -> 1 | D12: =+P!D12 -> 193720 | E12: ='C'!E12 -> 302030 | F12: =+D12+E12 -> 495750 | G12: =+F12-F11 -> -190 | H12: =IF(G12>0,G12,0) -> 0 | I12: =MAX($F$10:F12) -> 496080 | K12: =MAX(0,+I12-I11) -> 0 | L12: =MIN(F12:F41) -> 495750 | M12: =MAX(0,+L12-L11) -> 0 | N12: =MIN(M12,H12-K12) -> 0 | O12: =+K12+N12 -> 0 | P12: =+H12-O12 -> 0 | Q12: =MAX(0,IF(AND(K12=0,P12>0),0,Q11+K12+U11)) -> 0 | R12: =MAX(0,R11+P12+V11) -> 0 | S12: =IF(G12<0,G12,0) -> -190 | T12: =MIN(0,+S12+R11+V11) -> -190 | U12: =MAX(S12,IF(Q12>0,MAX(-Q12,S12),T12)) -> -190 | V12: =+S12-U12 -> 0 | Y12: =P!M12 -> 520 | Z12: =MAX(O12-Y12,0) -> 0
A13: =+A12+1 -> 43103 | B13: =YEAR(A13) -> 2018 | C13: =MONTH(A13) -> 1 | D13: =+P!D13 -> 194090 | E13: ='C'!E13 -> 301770 | F13: =+D13+E13 -> 495860 | G13: =+F13-F12 -> 110 | H13: =IF(G13>0,G13,0) -> 110 | I13: =MAX($F$10:F13) -> 496080 | K13: =MAX(0,+I13-I12) -> 0 | L13: =MIN(F13:F42) -> 495850 | M13: =MAX(0,+L13-L12) -> 100 | N13: =MIN(M13,H13-K13) -> 100 | O13: =+K13+N13 -> 100 | P13: =+H13-O13 -> 10 | Q13: =MAX(0,IF(AND(K13=0,P13>0),0,Q12+K13+U12)) -> 0 | R13: =MAX(0,R12+P13+V12) -> 10 | S13: =IF(G13<0,G13,0) -> 0 | T13: =MIN(0,+S13+R12+V12) -> 0 | U13: =MAX(S13,IF(Q13>0,MAX(-Q13,S13),T13)) -> 0 | V13: =+S13-U13 -> 0 | Y13: =P!M13 -> 370 | Z13: =MAX(O13-Y13,0) -> 0
A14: =+A13+1 -> 43104 | B14: =YEAR(A14) -> 2018 | C14: =MONTH(A14) -> 1 | D14: =+P!D14 -> 194780 | E14: ='C'!E14 -> 301130 | F14: =+D14+E14 -> 495910 | G14: =+F14-F13 -> 50 | H14: =IF(G14>0,G14,0) -> 50 | I14: =MAX($F$10:F14) -> 496080 | K14: =MAX(0,+I14-I13) -> 0 | L14: =MIN(F14:F43) -> 495850 | M14: =MAX(0,+L14-L13) -> 0 | N14: =MIN(M14,H14-K14) -> 0 | O14: =+K14+N14 -> 0 | P14: =+H14-O14 -> 50 | Q14: =MAX(0,IF(AND(K14=0,P14>0),0,Q13+K14+U13)) -> 0 | R14: =MAX(0,R13+P14+V13) -> 60 | S14: =IF(G14<0,G14,0) -> 0 | T14: =MIN(0,+S14+R13+V13) -> 0 | U14: =MAX(S14,IF(Q14>0,MAX(-Q14,S14),T14)) -> 0 | V14: =+S14-U14 -> 0 | Y14: =P!M14 -> 690 | Z14: =MAX(O14-Y14,0) -> 0
A15: =+A14+1 -> 43105 | B15: =YEAR(A15) -> 2018 | C15: =MONTH(A15) -> 1 | D15: =+P!D15 -> 195360 | E15: ='C'!E15 -> 300490 | F15: =+D15+E15 -> 495850 | G15: =+F15-F14 -> -60 | H15: =IF(G15>0,G15,0) -> 0 | I15: =MAX($F$10:F15) -> 496080 | K15: =MAX(0,+I15-I14) -> 0 | L15: =MIN(F15:F44) -> 495850 | M15: =MAX(0,+L15-L14) -> 0 | N15: =MIN(M15,H15-K15) -> 0 | O15: =+K15+N15 -> 0 | P15: =+H15-O15 -> 0 | Q15: =MAX(0,IF(AND(K15=0,P15>0),0,Q14+K15+U14)) -> 0 | R15: =MAX(0,R14+P15+V14) -> 60 | S15: =IF(G15<0,G15,0) -> -60 | T15: =MIN(0,+S15+R14+V14) -> 0 | U15: =MAX(S15,IF(Q15>0,MAX(-Q15,S15),T15)) -> 0 | V15: =+S15-U15 -> -60 | Y15: =P!M15 -> 580 | Z15: =MAX(O15-Y15,0) -> 0
A16: =+A15+1 -> 43106 | B16: =YEAR(A16) -> 2018 | C16: =MONTH(A16) -> 1 | D16: =+P!D16 -> 196210 | E16: ='C'!E16 -> 299970 | F16: =+D16+E16 -> 496180 | G16: =+F16-F15 -> 330 | H16: =IF(G16>0,G16,0) -> 330 | I16: =MAX($F$10:F16) -> 496180 | K16: =MAX(0,+I16-I15) -> 100 | L16: =MIN(F16:F45) -> 496180 | M16: =MAX(0,+L16-L15) -> 330 | N16: =MIN(M16,H16-K16) -> 230 | O16: =+K16+N16 -> 330 | P16: =+H16-O16 -> 0 | Q16: =MAX(0,IF(AND(K16=0,P16>0),0,Q15+K16+U15)) -> 100 | R16: =MAX(0,R15+P16+V15) -> 0 | S16: =IF(G16<0,G16,0) -> 0 | T16: =MIN(0,+S16+R15+V15) -> 0 | U16: =MAX(S16,IF(Q16>0,MAX(-Q16,S16),T16)) -> 0 | V16: =+S16-U16 -> 0 | Y16: =P!M16 -> 850 | Z16: =MAX(O16-Y16,0) -> 0
A17: =+A16+1 -> 43107 | B17: =YEAR(A17) -> 2018 | C17: =MONTH(A17) -> 1 | D17: =+P!D17 -> 197470 | E17: ='C'!E17 -> 299400 | F17: =+D17+E17 -> 496870 | G17: =+F17-F16 -> 690 | H17: =IF(G17>0,G17,0) -> 690 | I17: =MAX($F$10:F17) -> 496870 | K17: =MAX(0,+I17-I16) -> 690 | L17: =MIN(F17:F46) -> 496230 | M17: =MAX(0,+L17-L16) -> 50 | N17: =MIN(M17,H17-K17) -> 0 | O17: =+K17+N17 -> 690 | P17: =+H17-O17 -> 0 | Q17: =MAX(0,IF(AND(K17=0,P17>0),0,Q16+K17+U16)) -> 790 | R17: =MAX(0,R16+P17+V16) -> 0 | S17: =IF(G17<0,G17,0) -> 0 | T17: =MIN(0,+S17+R16+V16) -> 0 | U17: =MAX(S17,IF(Q17>0,MAX(-Q17,S17),T17)) -> 0 | V17: =+S17-U17 -> 0 | Y17: =P!M17 -> 1260 | Z17: =MAX(O17-Y17,0) -> 0
A18: =+A17+1 -> 43108 | B18: =YEAR(A18) -> 2018 | C18: =MONTH(A18) -> 1 | D18: =+P!D18 -> 197280 | E18: ='C'!E18 -> 300810 | F18: =+D18+E18 -> 498090 | G18: =+F18-F17 -> 1220 | H18: =IF(G18>0,G18,0) -> 1220 | I18: =MAX($F$10:F18) -> 498090 | K18: =MAX(0,+I18-I17) -> 1220 | L18: =MIN(F18:F47) -> 496130 | M18: =MAX(0,+L18-L17) -> 0 | N18: =MIN(M18,H18-K18) -> 0 | O18: =+K18+N18 -> 1220 | P18: =+H18-O18 -> 0 | Q18: =MAX(0,IF(AND(K18=0,P18>0),0,Q17+K18+U17)) -> 2010 | R18: =MAX(0,R17+P18+V17) -> 0 | S18: =IF(G18<0,G18,0) -> 0 | T18: =MIN(0,+S18+R17+V17) -> 0 | U18: =MAX(S18,IF(Q18>0,MAX(-Q18,S18),T18)) -> 0 | V18: =+S18-U18 -> 0 | Y18: =P!M18 -> 0 | Z18: =MAX(O18-Y18,0) -> 1220
A19: =+A18+1 -> 43109 | B19: =YEAR(A19) -> 2018 | C19: =MONTH(A19) -> 1 | D19: =+P!D19 -> 197580 | E19: ='C'!E19 -> 302160 | F19: =+D19+E19 -> 499740 | G19: =+F19-F18 -> 1650 | H19: =IF(G19>0,G19,0) -> 1650 | I19: =MAX($F$10:F19) -> 499740 | K19: =MAX(0,+I19-I18) -> 1650 | L19: =MIN(F19:F48) -> 495830 | M19: =MAX(0,+L19-L18) -> 0 | N19: =MIN(M19,H19-K19) -> 0 | O19: =+K19+N19 -> 1650 | P19: =+H19-O19 -> 0 | Q19: =MAX(0,IF(AND(K19=0,P19>0),0,Q18+K19+U18)) -> 3660 | R19: =MAX(0,R18+P19+V18) -> 0 | S19: =IF(G19<0,G19,0) -> 0 | T19: =MIN(0,+S19+R18+V18) -> 0 | U19: =MAX(S19,IF(Q19>0,MAX(-Q19,S19),T19)) -> 0 | V19: =+S19-U19 -> 0 | Y19: =P!M19 -> 110 | Z19: =MAX(O19-Y19,0) -> 1540
A20: =+A19+1 -> 43110 | B20: =YEAR(A20) -> 2018 | C20: =MONTH(A20) -> 1 | D20: =+P!D20 -> 196450 | E20: ='C'!E20 -> 303890 | F20: =+D20+E20 -> 500340 | G20: =+F20-F19 -> 600 | H20: =IF(G20>0,G20,0) -> 600 | I20: =MAX($F$10:F20) -> 500340 | K20: =MAX(0,+I20-I19) -> 600 | L20: =MIN(F20:F49) -> 495630 | M20: =MAX(0,+L20-L19) -> 0 | N20: =MIN(M20,H20-K20) -> 0 | O20: =+K20+N20 -> 600 | P20: =+H20-O20 -> 0 | Q20: =MAX(0,IF(AND(K20=0,P20>0),0,Q19+K20+U19)) -> 4260 | R20: =MAX(0,R19+P20+V19) -> 0 | S20: =IF(G20<0,G20,0) -> 0 | T20: =MIN(0,+S20+R19+V19) -> 0 | U20: =MAX(S20,IF(Q20>0,MAX(-Q20,S20),T20)) -> 0 | V20: =+S20-U20 -> 0 | Y20: =P!M20 -> 0 | Z20: =MAX(O20-Y20,0) -> 600
A21: =+A20+1 -> 43111 | B21: =YEAR(A21) -> 2018 | C21: =MONTH(A21) -> 1 | D21: =+P!D21 -> 195320 | E21: ='C'!E21 -> 305050 | F21: =+D21+E21 -> 500370 | G21: =+F21-F20 -> 30 | H21: =IF(G21>0,G21,0) -> 30 | I21: =MAX($F$10:F21) -> 500370 | K21: =MAX(0,+I21-I20) -> 30 | L21: =MIN(F21:F50) -> 495570 | M21: =MAX(0,+L21-L20) -> 0 | N21: =MIN(M21,H21-K21) -> 0 | O21: =+K21+N21 -> 30 | P21: =+H21-O21 -> 0 | Q21: =MAX(0,IF(AND(K21=0,P21>0),0,Q20+K21+U20)) -> 4290 | R21: =MAX(0,R20+P21+V20) -> 0 | S21: =IF(G21<0,G21,0) -> 0 | T21: =MIN(0,+S21+R20+V20) -> 0 | U21: =MAX(S21,IF(Q21>0,MAX(-Q21,S21),T21)) -> 0 | V21: =+S21-U21 -> 0 | Y21: =P!M21 -> 0 | Z21: =MAX(O21-Y21,0) -> 30
A22: =+A21+1 -> 43112 | B22: =YEAR(A22) -> 2018 | C22: =MONTH(A22) -> 1 | D22: =+P!D22 -> 194130 | E22: ='C'!E22 -> 306350 | F22: =+D22+E22 -> 500480 | G22: =+F22-F21 -> 110 | H22: =IF(G22>0,G22,0) -> 110 | I22: =MAX($F$10:F22) -> 500480 | K22: =MAX(0,+I22-I21) -> 110 | L22: =MIN(F22:F51) -> 495200 | M22: =MAX(0,+L22-L21) -> 0 | N22: =MIN(M22,H22-K22) -> 0 | O22: =+K22+N22 -> 110 | P22: =+H22-O22 -> 0 | Q22: =MAX(0,IF(AND(K22=0,P22>0),0,Q21+K22+U21)) -> 4400 | R22: =MAX(0,R21+P22+V21) -> 0 | S22: =IF(G22<0,G22,0) -> 0 | T22: =MIN(0,+S22+R21+V21) -> 0 | U22: =MAX(S22,IF(Q22>0,MAX(-Q22,S22),T22)) -> 0 | V22: =+S22-U22 -> 0 | Y22: =P!M22 -> 0 | Z22: =MAX(O22-Y22,0) -> 110
A23: =+A22+1 -> 43113 | B23: =YEAR(A23) -> 2018 | C23: =MONTH(A23) -> 1 | D23: =+P!D23 -> 192750 | E23: ='C'!E23 -> 307580 | F23: =+D23+E23 -> 500330 | G23: =+F23-F22 -> -150 | H23: =IF(G23>0,G23,0) -> 0 | I23: =MAX($F$10:F23) -> 500480 | K23: =MAX(0,+I23-I22) -> 0 | L23: =MIN(F23:F52) -> 494960 | M23: =MAX(0,+L23-L22) -> 0 | N23: =MIN(M23,H23-K23) -> 0 | O23: =+K23+N23 -> 0 | P23: =+H23-O23 -> 0 | Q23: =MAX(0,IF(AND(K23=0,P23>0),0,Q22+K23+U22)) -> 4400 | R23: =MAX(0,R22+P23+V22) -> 0 | S23: =IF(G23<0,G23,0) -> -150 | T23: =MIN(0,+S23+R22+V22) -> -150 | U23: =MAX(S23,IF(Q23>0,MAX(-Q23,S23),T23)) -> -150 | V23: =+S23-U23 -> 0 | Y23: =P!M23 -> 0 | Z23: =MAX(O23-Y23,0) -> 0
... A333: =+A332+1 -> 43423 | B333: =YEAR(A333) -> 2018 | C333: =MONTH(A333) -> 11 | D333: =+P!D333 -> 186760 | E333: ='C'!E333 -> 299460 | F333: =+D333+E333 -> 486220 | G333: =+F333-F332 -> -360 | H333: =IF(G333>0,G333,0) -> 0 | I333: =MAX($F$10:F333) -> 591510 | K333: =MAX(0,+I333-I332) -> 0 | L333: =MIN(F333:F362) -> 485910 | M333: =MAX(0,+L333-L332) -> 0 | N333: =MIN(M333,H333-K333) -> 0 | O333: =+K333+N333 -> 0 | P333: =+H333-O333 -> 0 | Q333: =MAX(0,IF(AND(K333=0,P333>0),0,Q332+K333+U332)) -> 0 | R333: =MAX(0,R332+P333+V332) -> 0 | S333: =IF(G333<0,G333,0) -> -360 | T333: =MIN(0,+S333+R332+V332) -> -360 | U333: =MAX(S333,IF(Q333>0,MAX(-Q333,S333),T333)) -> -360 | V333: =+S333-U333 -> 0 | Y333: =P!M333 -> 0 | Z333: =MAX(O333-Y333,0) -> 0
A334: =+A333+1 -> 43424 | B334: =YEAR(A334) -> 2018 | C334: =MONTH(A334) -> 11 | D334: =+P!D334 -> 186640 | E334: ='C'!E334 -> 299270 | F334: =+D334+E334 -> 485910 | G334: =+F334-F333 -> -310 | H334: =IF(G334>0,G334,0) -> 0 | I334: =MAX($F$334:F334) -> 485910 | J334: <--- | K334: =MAX(0,+I334-I333) -> 0 | L334: =MIN(F334:F363) -> 485910 | M334: =MAX(0,+L334-L333) -> 0 | N334: =MIN(M334,H334-K334) -> 0 | O334: =+K334+N334 -> 0 | P334: =+H334-O334 -> 0 | Q334: =MAX(0,IF(AND(K334=0,P334>0),0,Q333+K334+U333)) -> 0 | R334: =MAX(0,R333+P334+V333) -> 0 | S334: =IF(G334<0,G334,0) -> -310 | T334: =MIN(0,+S334+R333+V333) -> -310 | U334: =MAX(S334,IF(Q334>0,MAX(-Q334,S334),T334)) -> -310 | V334: =+S334-U334 -> 0 | Y334: =P!M334 -> 0 | Z334: =MAX(O334-Y334,0) -> 0
A335: =+A334+1 -> 43425 | B335: =YEAR(A335) -> 2018 | C335: =MONTH(A335) -> 11 | D335: =+P!D335 -> 186680 | E335: ='C'!E335 -> 299850 | F335: =+D335+E335 -> 486530 | G335: =+F335-F334 -> 620 | H335: =IF(G335>0,G335,0) -> 620 | I335: =MAX($F$334:F335) -> 486530 | K335: =MAX(0,+I335-I334) -> 620 | L335: =MIN(F335:F364) -> 486010 | M335: =MAX(0,+L335-L334) -> 100 | N335: =MIN(M335,H335-K335) -> 0 | O335: =+K335+N335 -> 620 | P335: =+H335-O335 -> 0 | Q335: =MAX(0,IF(AND(K335=0,P335>0),0,Q334+K335+U334)) -> 310 | R335: =MAX(0,R334+P335+V334) -> 0 | S335: =IF(G335<0,G335,0) -> 0 | T335: =MIN(0,+S335+R334+V334) -> 0 | U335: =MAX(S335,IF(Q335>0,MAX(-Q335,S335),T335)) -> 0 | V335: =+S335-U335 -> 0 | Y335: =P!M335 -> 0 | Z335: =MAX(O335-Y335,0) -> 620
A336: =+A335+1 -> 43426 | B336: =YEAR(A336) -> 2018 | C336: =MONTH(A336) -> 11 | D336: =+P!D336 -> 186620 | E336: ='C'!E336 -> 299720 | F336: =+D336+E336 -> 486340 | G336: =+F336-F335 -> -190 | H336: =IF(G336>0,G336,0) -> 0 | I336: =MAX($F$334:F336) -> 486530 | K336: =MAX(0,+I336-I335) -> 0 | L336: =MIN(F336:F365) -> 486010 | M336: =MAX(0,+L336-L335) -> 0 | N336: =MIN(M336,H336-K336) -> 0 | O336: =+K336+N336 -> 0 | P336: =+H336-O336 -> 0 | Q336: =MAX(0,IF(AND(K336=0,P336>0),0,Q335+K336+U335)) -> 310 | R336: =MAX(0,R335+P336+V335) -> 0 | S336: =IF(G336<0,G336,0) -> -190 | T336: =MIN(0,+S336+R335+V335) -> -190 | U336: =MAX(S336,IF(Q336>0,MAX(-Q336,S336),T336)) -> -190 | V336: =+S336-U336 -> 0 | Y336: =P!M336 -> 0 | Z336: =MAX(O336-Y336,0) -> 0
A337: =+A336+1 -> 43427 | B337: =YEAR(A337) -> 2018 | C337: =MONTH(A337) -> 11 | D337: =+P!D337 -> 186740 | E337: ='C'!E337 -> 299910 | F337: =+D337+E337 -> 486650 | G337: =+F337-F336 -> 310 | H337: =IF(G337>0,G337,0) -> 310 | I337: =MAX($F$334:F337) -> 486650 | K337: =MAX(0,+I337-I336) -> 120 | L337: =MIN(F337:F366) -> 486010 | M337: =MAX(0,+L337-L336) -> 0 | N337: =MIN(M337,H337-K337) -> 0 | O337: =+K337+N337 -> 120 | P337: =+H337-O337 -> 190 | Q337: =MAX(0,IF(AND(K337=0,P337>0),0,Q336+K337+U336)) -> 240 | R337: =MAX(0,R336+P337+V336) -> 190 | S337: =IF(G337<0,G337,0) -> 0 | T337: =MIN(0,+S337+R336+V336) -> 0 | U337: =MAX(S337,IF(Q337>0,MAX(-Q337,S337),T337)) -> 0 | V337: =+S337-U337 -> 0 | Y337: =P!M337 -> 0 | Z337: =MAX(O337-Y337,0) -> 120
A338: =+A337+1 -> 43428 | B338: =YEAR(A338) -> 2018 | C338: =MONTH(A338) -> 11 | D338: =+P!D338 -> 187020 | E338: ='C'!E338 -> 299780 | F338: =+D338+E338 -> 486800 | G338: =+F338-F337 -> 150 | H338: =IF(G338>0,G338,0) -> 150 | I338: =MAX($F$334:F338) -> 486800 | K338: =MAX(0,+I338-I337) -> 150 | L338: =MIN(F338:F367) -> 486010 | M338: =MAX(0,+L338-L337) -> 0 | N338: =MIN(M338,H338-K338) -> 0 | O338: =+K338+N338 -> 150 | P338: =+H338-O338 -> 0 | Q338: =MAX(0,IF(AND(K338=0,P338>0),0,Q337+K338+U337)) -> 390 | R338: =MAX(0,R337+P338+V337) -> 190 | S338: =IF(G338<0,G338,0) -> 0 | T338: =MIN(0,+S338+R337+V337) -> 0 | U338: =MAX(S338,IF(Q338>0,MAX(-Q338,S338),T338)) -> 0 | V338: =+S338-U338 -> 0 | Y338: =P!M338 -> 0 | Z338: =MAX(O338-Y338,0) -> 150
A339: =+A338+1 -> 43429 | B339: =YEAR(A339) -> 2018 | C339: =MONTH(A339) -> 11 | D339: =+P!D339 -> 187290 | E339: ='C'!E339 -> 299270 | F339: =+D339+E339 -> 486560 | G339: =+F339-F338 -> -240 | H339: =IF(G339>0,G339,0) -> 0 | I339: =MAX($F$334:F339) -> 486800 | K339: =MAX(0,+I339-I338) -> 0 | L339: =MIN(F339:F368) -> 486010 | M339: =MAX(0,+L339-L338) -> 0 | N339: =MIN(M339,H339-K339) -> 0 | O339: =+K339+N339 -> 0 | P339: =+H339-O339 -> 0 | Q339: =MAX(0,IF(AND(K339=0,P339>0),0,Q338+K339+U338)) -> 390 | R339: =MAX(0,R338+P339+V338) -> 190 | S339: =IF(G339<0,G339,0) -> -240 | T339: =MIN(0,+S339+R338+V338) -> -50 | U339: =MAX(S339,IF(Q339>0,MAX(-Q339,S339),T339)) -> -240 | V339: =+S339-U339 -> 0 | Y339: =P!M339 -> 0 | Z339: =MAX(O339-Y339,0) -> 0
A340: =+A339+1 -> 43430 | B340: =YEAR(A340) -> 2018 | C340: =MONTH(A340) -> 11 | D340: =+P!D340 -> 187440 | E340: ='C'!E340 -> 298820 | F340: =+D340+E340 -> 486260 | G340: =+F340-F339 -> -300 | H340: =IF(G340>0,G340,0) -> 0 | I340: =MAX($F$334:F340) -> 486800 | K340: =MAX(0,+I340-I339) -> 0 | L340: =MIN(F340:F369) -> 486010 | M340: =MAX(0,+L340-L339) -> 0 | N340: =MIN(M340,H340-K340) -> 0 | O340: =+K340+N340 -> 0 | P340: =+H340-O340 -> 0 | Q340: =MAX(0,IF(AND(K340=0,P340>0),0,Q339+K340+U339)) -> 150 | R340: =MAX(0,R339+P340+V339) -> 190 | S340: =IF(G340<0,G340,0) -> -300 | T340: =MIN(0,+S340+R339+V339) -> -110 | U340: =MAX(S340,IF(Q340>0,MAX(-Q340,S340),T340)) -> -150 | V340: =+S340-U340 -> -150 | Y340: =P!M340 -> 0 | Z340: =MAX(O340-Y340,0) -> 0
A341: =+A340+1 -> 43431 | B341: =YEAR(A341) -> 2018 | C341: =MONTH(A341) -> 11 | D341: =+P!D341 -> 187570 | E341: ='C'!E341 -> 298440 | F341: =+D341+E341 -> 486010 | G341: =+F341-F340 -> -250 | H341: =IF(G341>0,G341,0) -> 0 | I341: =MAX($F$334:F341) -> 486800 | K341: =MAX(0,+I341-I340) -> 0 | L341: =MIN(F341:F370) -> 486010 | M341: =MAX(0,+L341-L340) -> 0 | N341: =MIN(M341,H341-K341) -> 0 | O341: =+K341+N341 -> 0 | P341: =+H341-O341 -> 0 | Q341: =MAX(0,IF(AND(K341=0,P341>0),0,Q340+K341+U340)) -> 0 | R341: =MAX(0,R340+P341+V340) -> 40 | S341: =IF(G341<0,G341,0) -> -250 | T341: =MIN(0,+S341+R340+V340) -> -210 | U341: =MAX(S341,IF(Q341>0,MAX(-Q341,S341),T341)) -> -210 | V341: =+S341-U341 -> -40 | Y341: =P!M341 -> 0 | Z341: =MAX(O341-Y341,0) -> 0
A342: =+A341+1 -> 43432 | B342: =YEAR(A342) -> 2018 | C342: =MONTH(A342) -> 11 | D342: =+P!D342 -> 187970 | E342: ='C'!E342 -> 298060 | F342: =+D342+E342 -> 486030 | G342: =+F342-F341 -> 20 | H342: =IF(G342>0,G342,0) -> 20 | I342: =MAX($F$334:F342) -> 486800 | K342: =MAX(0,+I342-I341) -> 0 | L342: =MIN(F342:F371) -> 486030 | M342: =MAX(0,+L342-L341) -> 20 | N342: =MIN(M342,H342-K342) -> 20 | O342: =+K342+N342 -> 20 | P342: =+H342-O342 -> 0 | Q342: =MAX(0,IF(AND(K342=0,P342>0),0,Q341+K342+U341)) -> 0 | R342: =MAX(0,R341+P342+V341) -> 0 | S342: =IF(G342<0,G342,0) -> 0 | T342: =MIN(0,+S342+R341+V341) -> 0 | U342: =MAX(S342,IF(Q342>0,MAX(-Q342,S342),T342)) -> 0 | V342: =+S342-U342 -> 0 | Y342: =P!M342 -> 0 | Z342: =MAX(O342-Y342,0) -> 20
A343: =+A342+1 -> 43433 | B343: =YEAR(A343) -> 2018 | C343: =MONTH(A343) -> 11 | D343: =+P!D343 -> 188710 | E343: ='C'!E343 -> 297930 | F343: =+D343+E343 -> 486640 | G343: =+F343-F342 -> 610 | H343: =IF(G343>0,G343,0) -> 610 | I343: =MAX($F$334:F343) -> 486800 | K343: =MAX(0,+I343-I342) -> 0 | L343: =MIN(F343:F372) -> 486270 | M343: =MAX(0,+L343-L342) -> 240 | N343: =MIN(M343,H343-K343) -> 240 | O343: =+K343+N343 -> 240 | P343: =+H343-O343 -> 370 | Q343: =MAX(0,IF(AND(K343=0,P343>0),0,Q342+K343+U342)) -> 0 | R343: =MAX(0,R342+P343+V342) -> 370 | S343: =IF(G343<0,G343,0) -> 0 | T343: =MIN(0,+S343+R342+V342) -> 0 | U343: =MAX(S343,IF(Q343>0,MAX(-Q343,S343),T343)) -> 0 | V343: =+S343-U343 -> 0 | Y343: =P!M343 -> 0 | Z343: =MAX(O343-Y343,0) -> 240
A344: =+A343+1 -> 43434 | B344: =YEAR(A344) -> 2018 | C344: =MONTH(A344) -> 11 | D344: =+P!D344 -> 189780 | E344: ='C'!E344 -> 297230 | F344: =+D344+E344 -> 487010 | G344: =+F344-F343 -> 370 | H344: =IF(G344>0,G344,0) -> 370 | I344: =MAX($F$334:F344) -> 487010 | K344: =MAX(0,+I344-I343) -> 210 | L344: =MIN(F344:F373) -> 486270 | M344: =MAX(0,+L344-L343) -> 0 | N344: =MIN(M344,H344-K344) -> 0 | O344: =+K344+N344 -> 210 | P344: =+H344-O344 -> 160 | Q344: =MAX(0,IF(AND(K344=0,P344>0),0,Q343+K344+U343)) -> 210 | R344: =MAX(0,R343+P344+V343) -> 530 | S344: =IF(G344<0,G344,0) -> 0 | T344: =MIN(0,+S344+R343+V343) -> 0 | U344: =MAX(S344,IF(Q344>0,MAX(-Q344,S344),T344)) -> 0 | V344: =+S344-U344 -> 0 | Y344: =P!M344 -> 0 | Z344: =MAX(O344-Y344,0) -> 210
A345: =+A344+1 -> 43435 | B345: =YEAR(A345) -> 2018 | C345: =MONTH(A345) -> 12 | D345: =+P!D345 -> 190740 | E345: ='C'!E345 -> 296850 | F345: =+D345+E345 -> 487590 | G345: =+F345-F344 -> 580 | H345: =IF(G345>0,G345,0) -> 580 | I345: =MAX($F$334:F345) -> 487590 | K345: =MAX(0,+I345-I344) -> 580 | L345: =MIN(F345:F374) -> 486270 | M345: =MAX(0,+L345-L344) -> 0 | N345: =MIN(M345,H345-K345) -> 0 | O345: =+K345+N345 -> 580 | P345: =+H345-O345 -> 0 | Q345: =MAX(0,IF(AND(K345=0,P345>0),0,Q344+K345+U344)) -> 790 | R345: =MAX(0,R344+P345+V344) -> 530 | S345: =IF(G345<0,G345,0) -> 0 | T345: =MIN(0,+S345+R344+V344) -> 0 | U345: =MAX(S345,IF(Q345>0,MAX(-Q345,S345),T345)) -> 0 | V345: =+S345-U345 -> 0 | Y345: =P!M345 -> 0 | Z345: =MAX(O345-Y345,0) -> 580
